Workbook
Name Scenario: rNPV!$A$1

Sheet DCF
A1: FY | B1: =YEAR(DATEVALUE("JAN-2025")) -> 2025 | C1: =YEAR(DATEVALUE("JAN-2026")) -> 2026 | D1: =YEAR(DATEVALUE("JAN-2027")) -> 2027 | E1: =YEAR(DATEVALUE("JAN-2028")) -> 2028 | F1: =YEAR(DATEVALUE("JAN-2029")) -> 2029
A2: EBIT | B2: ='[1]Income Statement'!G8 -> 865.81174 | C2: ='[1]Income Statement'!H8 -> 920.46118 | D2: ='[1]Income Statement'!I8 -> 978.74064 | E2: ='[1]Income Statement'!J8 -> 1040.9024 | F2: ='[1]Income Statement'!K8 -> 1107.2169 | H2: Tax Rate | I2: ='[1]Balance Sheet'!$N$7 -> 0.105675 | O2: Bull
A3: Net Operating Profit After Tax | B3: =B2*(1-DCF!$I$2) -> 774.31709 | C3: =C2*(1-DCF!$I$2) -> 823.19145 | D3: =D2*(1-DCF!$I$2) -> 875.31222 | E3: =E2*(1-DCF!$I$2) -> 930.90503 | F3: =F2*(1-DCF!$I$2) -> 990.21176 | H3: Risk Free Rate | I3: 0.041 | O3: Central
A4: Depreciation and Amortisation | B4: ='[1]Income Statement'!G39 -> 474.10524 | C4: ='[1]Income Statement'!H39 -> 504.03044 | D4: ='[1]Income Statement'!I39 -> 535.94338 | E4: ='[1]Income Statement'!J39 -> 569.9822 | F4: ='[1]Income Statement'!K39 -> 606.29502 | H4: WACC | I4: =(((I8/(I8+I6))*I7)+((I6/(I8+I6))*I5))*(1-I2) -> 0.057975388 | O4: Bear
A5: Capital Expenditure | B5: ='[1]Balance Sheet'!G53 -> -477.5031 | C5: ='[1]Balance Sheet'!H53 -> -507.64277 | D5: ='[1]Balance Sheet'!I53 -> -539.78442 | E5: ='[1]Balance Sheet'!J53 -> -574.0672 | F5: ='[1]Balance Sheet'!K53 -> -610.64026 | H5: Cost of Debt | I5: =0.056 -> 0.056
A6: Change in Net Working Capital | B6: =-'[1]Balance Sheet'!$G$52 -> -149.35646 | C6: =-'[1]Balance Sheet'!$G$52 -> -149.35646 | D6: =-'[1]Balance Sheet'!$G$52 -> -149.35646 | E6: =-'[1]Balance Sheet'!$G$52 -> -149.35646 | F6: =-'[1]Balance Sheet'!$G$52 -> -149.35646 | H6: Market Value of Debt | I6: ='[1]Balance Sheet'!$F$49 -> 2986
A7: Free Cash Flow | B7: =SUM(B3:B6) -> 621.56277 | C7: =SUM(C3:C6) -> 670.22266 | D7: =SUM(D3:D6) -> 722.11472 | E7: =SUM(E3:E6) -> 777.46357 | F7: =SUM(F3:F6) -> 836.51006 | H7: Cost of Equity | I7: =I3+(I10*I11) -> 0.06646
A8: Discounted Value | B8: =B7/((1+DCF!$I$4)^(DCF!B1-2024)) -> 587.50211 | C8: =C7/((1+DCF!$I$4)^(DCF!C1-2024)) -> 598.78095 | D8: =D7/((1+DCF!$I$4)^(DCF!D1-2024)) -> 609.78888 | E8: =E7/((1+DCF!$I$4)^(DCF!E1-2024)) -> 620.55144 | F8: =F7/((1+DCF!$I$4)^(DCF!F1-2024)) -> 631.09297 | H8: Market Value of Equity | I8: =I9*('[1]Income Statement'!$F$25*'[1]Income Statement'!$N$8) -> 16127.16
H9: Current Share Price | I9: 36.82
B10: Perpetuity | D10: Multiple Method | H10: Beta | I10: 0.67
A11: Present Value of Terminal Value | B11: =((F7*(1+DCF!I12))/(DCF!I4-DCF!I12))/((1+I4)^5) -> 16950.843 | D11: =((F2+F4)*I13)/((1+I4)^5) -> 15616.58 | H11: Equity Risk Premium | I11: 0.038
A12: Enterprise Value | B12: =SUM(B8:F8)+B11 -> 19998.559 | D12: =SUM(B8:F8)+D11 -> 18664.297 | H12: Perpetuity Growth | I12: 0.02
H13: EV/EBITDA Multiple | I13: =I8/'[1]Income Statement'!$F$40 -> 12.08027
A14: Net Debt:
A15: Short Term Debt | B15: ='[1]Balance Sheet'!$F$22 -> 2 | G15: Perpetuity Approach
A16: Long Term Debt | B16: ='[1]Balance Sheet'!$F$28 -> 3123 | G16: =B12 -> 19998.559 | H16: =I16-0.005 -> 0.047975388 | I16: =J16-0.005 -> 0.052975388 | J16: 0.057975388 | K16: =J16+0.005 -> 0.062975388 | L16: =K16+0.005 -> 0.067975388
A17: Current Portion of Long Term Debt | B17: ='[1]Balance Sheet'!$F$23 -> 0 | G17: =G18-0.005 -> 0.01 | H17: 20738.046 | I17: 18279.269 | J17: 16333.777 | K17: 14756.216 | L17: 13451.376
A18: Current Portion of Leases | B18: ='[1]Balance Sheet'!$F$24 -> 61 | G18: =G19-0.005 -> 0.015 | H18: 23507.185 | I18: 20363.981 | J18: 17952.977 | K18: 16045.224 | L18: 14498.211
A19: Pension and Post-Retirement Bonuses | B19: ='[1]Balance Sheet'!$F$30 -> 79 | G19: 0.02 | H19: 27266.171 | I19: 23080.897 | J19: 19998.559 | K19: 17634.173 | L19: 15763.249
A20: Long Term Leases | B20: ='[1]Balance Sheet'!$F$29 -> 135 | G20: =G19+0.005 -> 0.025 | H20: 32661.251 | I20: 26768.993 | J20: 22664.477 | K20: 19641.538 | L20: 17322.651
A21: Long-Term Deffered Tax Liabilities | B21: ='[1]Balance Sheet'!$F$31 -> 31 | G21: =G20+0.005 -> 0.03 | H21: 41057.701 | I21: 32062.328 | J21: 26283.346 | K21: 22257.649 | L21: 19292.687
A22: Other Long-Term Liabilities | B22: ='[1]Balance Sheet'!$F$32 -> 190 | I22: Case: | J22: Bear
A23: Cash and Equivalents | B23: ='[1]Balance Sheet'!$F$3 -> 619 | H23: Enterprise Value: | I23: =IF(J22="Bull",I20,IF(J22="Bear",K18,IF(J22="Central",J19,"Error"))) -> 16045.224 | K23: Equity Value: | L23: =I23-B25 -> 13059.224
A24: Long Term Investments | B24: ='[1]Balance Sheet'!$F$12 -> 16 | I24: EqV Per ADR Share: | J24: =L23/B36*2 -> 29.81558
A25: Net Debt | B25: =(SUM(B15:B22)+(-1*SUM(B23:B24))) -> 2986 | I25: Upside: | J25: =J24-B29 -> -7.0044196 | K25: =J25/B29 -> -0.1902341
A26: Equity Value | B26: =B12-B25 -> 17012.559 | D26: =D12-B25 -> 15678.297
A27: Equity Value per Ordinary Share | B27: =B26/B36 -> 19.420729 | D27: =D26/B36 -> 17.897599 | G27: EBITDA Multiple Approach
A28: Equity Value Per ADR Share | B28: =B27*2 -> 38.841459 | D28: =D27*2 -> 35.795198 | G28: =D12 -> 18664.297 | H28: =I28-0.005 -> 0.047975388 | I28: =J28-0.005 -> 0.052975388 | J28: 0.057975388 | K28: =J28+0.005 -> 0.062975388 | L28: =K28+0.005 -> 0.067975388
A29: Current price | B29: =DCF!$I$9 -> 36.82 | D29: =DCF!$I$9 -> 36.82 | G29: =G30-1 -> 10.08 | H29: 16801.598 | I29: 16435.026 | J29: 16078.479 | K29: 15731.635 | L29: 15394.182
A30: Upside | B30: =B28-B29 -> 2.021459 | C30: =B30/B29 -> 0.054901113 | D30: =D28-D29 -> -1.0248023 | E30: =D30/D29 -> -0.027832763 | G30: =G31-1 -> 11.08 | H30: 18157.198 | I30: 17758.746 | J30: 17371.214 | K30: 16994.25 | L30: 16627.516
G31: 12.08 | H31: 19512.799 | I31: 19082.465 | J31: 18663.948 | K31: 18256.865 | L31: 17860.851
G32: =G31+1 -> 13.08 | H32: 20868.399 | I32: 20406.185 | J32: 19956.682 | K32: 19519.481 | L32: 19094.186
G33: =G32+1 -> 14.08 | H33: 22224 | I33: 21729.905 | J33: 21249.417 | K33: 20782.096 | L33: 20327.52
A34: Shares Outstanding | B34: ='[1]Income Statement'!$F$24 -> 873 | I34: Case: | J34: Bear
A35: Impact of Dilutive Shares | B35: 3 | H35: Enterprise Value: | I35: =IF(J34="Bull",I32,IF(J34="Bear",K30,IF(J34="Central",J31,"Error"))) -> 16994.25 | K35: Equity Value: | L35: =I35-B37 -> 16994.25
A36: Diluted Shares Outstanding | B36: =B34+B35 -> 876 | I36: EqV Per ADR Share: | J36: =L35/B36*2 -> 38.799658
I37: Upside: | J37: =J36-B29 -> 1.9796576 | K37: =J37/B29 -> 0.053765823

Sheet SOTP
B1: Orthopaedics | H1: Sports Med and ENT | N1: Advanced Wound | T1: Totals
A2: FY | B2: =YEAR(DATEVALUE("JAN-2024")) -> 2024 | C2: =YEAR(DATEVALUE("JAN-2025")) -> 2025 | D2: =YEAR(DATEVALUE("JAN-2026")) -> 2026 | E2: =YEAR(DATEVALUE("JAN-2027")) -> 2027 | F2: =YEAR(DATEVALUE("JAN-2028")) -> 2028 | G2: =YEAR(DATEVALUE("JAN-2029")) -> 2029 | H2: =YEAR(DATEVALUE("JAN-2024")) -> 2024 | I2: =YEAR(DATEVALUE("JAN-2025")) -> 2025 | J2: =YEAR(DATEVALUE("JAN-2026")) -> 2026 | K2: =YEAR(DATEVALUE("JAN-2027")) -> 2027 | L2: =YEAR(DATEVALUE("JAN-2028")) -> 2028 | M2: =YEAR(DATEVALUE("JAN-2029")) -> 2029 | N2: =YEAR(DATEVALUE("JAN-2024")) -> 2024 | O2: =YEAR(DATEVALUE("JAN-2025")) -> 2025 | P2: =YEAR(DATEVALUE("JAN-2026")) -> 2026 | Q2: =YEAR(DATEVALUE("JAN-2027")) -> 2027 | R2: =YEAR(DATEVALUE("JAN-2028")) -> 2028 | S2: =YEAR(DATEVALUE("JAN-2029")) -> 2029 | T2: 2024 | V2: Tax Rate | W2: ='[1]Balance Sheet'!$N$7 -> 0.105675 | AA2: Bear
A3: Revenue | B3: ='[1]Income Statement'!$F$43 -> 2305 | C3: ='[1]Income Statement'!G43 -> 2413.6991 | D3: ='[1]Income Statement'!H43 -> 2527.5243 | E3: ='[1]Income Statement'!I43 -> 2646.7172 | F3: ='[1]Income Statement'!J43 -> 2771.531 | G3: ='[1]Income Statement'!K43 -> 2902.2308 | H3: ='[1]Income Statement'!$F$44 -> 1824 | I3: ='[1]Income Statement'!G44 -> 1972.7566 | J3: ='[1]Income Statement'!H44 -> 2133.6451 | K3: ='[1]Income Statement'!I44 -> 2307.6548 | L3: ='[1]Income Statement'!J44 -> 2495.856 | M3: ='[1]Income Statement'!K44 -> 2699.4059 | N3: ='[1]Income Statement'!$F$45 -> 1681 | O3: ='[1]Income Statement'!G45 -> 1789.1297 | P3: ='[1]Income Statement'!H45 -> 1904.2147 | Q3: ='[1]Income Statement'!I45 -> 2026.7026 | R3: ='[1]Income Statement'!J45 -> 2157.0695 | S3: ='[1]Income Statement'!K45 -> 2295.8221 | T3: ='[1]Income Statement'!F2 -> 5810 | V3: Risk Free Rate | W3: 0.041 | AA3: Central
A4: EBIT | B4: 265 | C4: =C3*$B$5 -> 277.49686 | D4: =D3*$B$5 -> 290.58305 | E4: =E3*$B$5 -> 304.28636 | F4: =F3*$B$5 -> 318.63589 | G4: =G3*$B$5 -> 333.66211 | H4: 437 | I4: =I3*$H$5 -> 472.6396 | J4: =J3*$H$5 -> 511.1858 | K4: =K3*$H$5 -> 552.87563 | L4: =L3*$H$5 -> 597.96549 | M4: =M3*$H$5 -> 646.73266 | N4: 399 | O4: =O3*$N$5 -> 424.66552 | P4: =P3*$N$5 -> 451.98196 | Q4: =Q3*$N$5 -> 481.05553 | R4: =R3*$N$5 -> 511.99924 | S4: =S3*$N$5 -> 544.93339 | T4: ='[1]Income Statement'!F8 -> 886 | V4: WACC | W4: =(((W8/(W8+W6))*W7)+((W6/(W8+W6))*W5))*(1-W2) -> 0.057975388 | AA4: Bull
A5: EBIT Margin | B5: =B4/B3 -> 0.11496746 | H5: =H4/H3 -> 0.23958333 | N5: =N4/N3 -> 0.23735872 | V5: Cost of Debt | W5: =0.056 -> 0.056
A6: Net Operating Profit after Tax | B6: =B4*(1-$W$2) -> 236.99613 | C6: =C4*(1-$W$2) -> 248.17238 | D6: =D4*(1-$W$2) -> 259.87569 | E6: =E4*(1-$W$2) -> 272.1309 | F6: =F4*(1-$W$2) -> 284.96404 | G6: =G4*(1-$W$2) -> 298.40237 | H6: =H4*(1-$W$2) -> 390.82003 | I6: =I4*(1-$W$2) -> 422.69341 | ... S6: =S4*(1-$W$2) -> 487.34755 | V6: Market Value of Debt | W6: ='[1]Balance Sheet'!$F$49 -> 2986
V7: Cost of Equity | W7: =W3+(W10*W11) -> 0.06646
A8: Depreciation and Amortisation | B8: 213 | C8: =$B$9*'[1]Income Statement'!G39 -> 224.90961 | D8: =$B$9*'[1]Income Statement'!H39 -> 239.10575 | E8: =$B$9*'[1]Income Statement'!I39 -> 254.24485 | F8: =$B$9*'[1]Income Statement'!J39 -> 270.39245 | G8: =$B$9*'[1]Income Statement'!K39 -> 287.61879 | H8: 98 | I8: =$H$9*'[1]Income Statement'!G39 -> 103.47954 | J8: =$H$9*'[1]Income Statement'!H39 -> 110.0111 | K8: =$H$9*'[1]Income Statement'!I39 -> 116.97651 | L8: =$H$9*'[1]Income Statement'!J39 -> 124.40591 | M8: =$H$9*'[1]Income Statement'!K39 -> 132.33165 | N8: 62 | O8: =$N$9*'[1]Income Statement'!G39 -> 65.466648 | P8: =$N$9*'[1]Income Statement'!H39 -> 69.598858 | Q8: =$N$9*'[1]Income Statement'!I39 -> 74.005544 | R8: =$N$9*'[1]Income Statement'!J39 -> 78.705782 | S8: =$N$9*'[1]Income Statement'!K39 -> 83.720024 | V8: Market Value of Equity | W8: =W9*('[1]Income Statement'!$F$25*'[1]Income Statement'!$N$8) -> 16127.16
A9: D&A Proportion | B9: =B8/'[1]Income Statement'!F39 -> 0.47438753 | H9: =H8/'[1]Income Statement'!F39 -> 0.21826281 | N9: =N8/'[1]Income Statement'!F39 -> 0.13808463 | V9: Current Share Price | W9: 36.82
V10: Beta | W10: 0.67
A11: Capital Expenditure | B11: ='[1]Balance Sheet'!F53*$B$13 -> -165.05415 | C11: ='[1]Balance Sheet'!G53*$B$13 -> -206.86055 | D11: ='[1]Balance Sheet'!H53*$B$13 -> -219.91745 | E11: ='[1]Balance Sheet'!I53*$B$13 -> -233.84163 | F11: ='[1]Balance Sheet'!J53*$B$13 -> -248.69337 | G11: ='[1]Balance Sheet'!K53*$B$13 -> -264.5373 | H11: ='[1]Balance Sheet'!F53*$H$13 -> -112.22064 | I11: ='[1]Balance Sheet'!G53*$H$13 -> -140.64489 | J11: ='[1]Balance Sheet'!H53*$H$13 -> -149.5223 | K11: ='[1]Balance Sheet'!I53*$H$13 -> -158.98938 | L11: ='[1]Balance Sheet'!J53*$H$13 -> -169.08711 | M11: ='[1]Balance Sheet'!K53*$H$13 -> -179.85943 | N11: ='[1]Balance Sheet'!F53*$N$13 -> -103.72521 | O11: ='[1]Balance Sheet'!G53*$N$13 -> -129.99766 | P11: ='[1]Balance Sheet'!H53*$N$13 -> -138.20302 | Q11: ='[1]Balance Sheet'!I53*$N$13 -> -146.95341 | R11: ='[1]Balance Sheet'!J53*$N$13 -> -156.28672 | S11: ='[1]Balance Sheet'!K53*$N$13 -> -166.24354 | V11: Equity Risk Premium | W11: 0.038
A12: Change in Net Working Capital | B12: =DCF!B6*$B$13 -> -64.703159 | C12: =DCF!B6*$B$13 -> -64.703159 | D12: =DCF!C6*$B$13 -> -64.703159 | E12: =DCF!D6*$B$13 -> -64.703159 | F12: =DCF!E6*$B$13 -> -64.703159 | G12: =DCF!F6*$B$13 -> -64.703159 | H12: =DCF!B6*$H$13 -> -43.991805 | I12: =DCF!B6*$H$13 -> -43.991805 | J12: =DCF!C6*$H$13 -> -43.991805 | K12: =DCF!D6*$H$13 -> -43.991805 | L12: =DCF!E6*$H$13 -> -43.991805 | M12: =DCF!F6*$H$13 -> -43.991805 | N12: =DCF!B6*$N$13 -> -40.661495 | O12: =DCF!B6*$N$13 -> -40.661495 | P12: =DCF!C6*$N$13 -> -40.661495 | Q12: =DCF!D6*$N$13 -> -40.661495 | R12: =DCF!E6*$N$13 -> -40.661495 | S12: =DCF!F6*$N$13 -> -40.661495 | V12: Perpetuity Growth | W12: 0.02
A13: Segment Spending Proportion | B13: =(B3-B4)/((B3-B4)+(H3-H4)+(N3-N4)) -> 0.433213 | H13: =(H3-H4)/((B3-B4)+(H3-H4)+(N3-N4)) -> 0.29454237 | N13: =(N3-N4)/((B3-B4)+(H3-H4)+(N3-N4)) -> 0.27224464 | V13: EV/EBITDA Multiple | W13: =W8/'[1]Income Statement'!$F$40 -> 12.08027
A15: Free Cash Flow | C15: =SUM(C12,C11,C8,C6) -> 201.51829 | D15: =SUM(D12,D11,D8,D6) -> 214.36084 | E15: =SUM(E12,E11,E8,E6) -> 227.83097 | F15: =SUM(F12,F11,F8,F6) -> 241.95996 | G15: =SUM(G12,G11,G8,G6) -> 256.78071 | I15: =SUM(I12,I11,I8,I6) -> 341.53626 | J15: =SUM(J12,J11,J8,J6) -> 373.66323 | K15: =SUM(K12,K11,K8,K6) -> 408.44582 | L15: =SUM(L12,L11,L8,L6) -> 446.10249 | M15: =SUM(M12,M11,M8,M6) -> 486.8696 | O15: =SUM(O12,O11,O8,O6) -> 274.59648 | P15: =SUM(P12,P11,P8,P6) -> 294.95311 | Q15: =SUM(Q12,Q11,Q8,Q6) -> 316.61062 | R15: =SUM(R12,R11,R8,R6) -> 339.65129 | S15: =SUM(S12,S11,S8,S6) -> 364.16254
A16: Discounted FCF | C16: =C15/((1+$W$4)^(C2-2024)) -> 190.4754 | D16: =D15/((1+$W$4)^(D2-2024)) -> 191.51126 | E16: =E15/((1+$W$4)^(E2-2024)) -> 192.39158 | F16: =F15/((1+$W$4)^(F2-2024)) -> 193.12622 | G16: =G15/((1+$W$4)^(G2-2024)) -> 193.72451 | I16: =I15/((1+$W$4)^(I2-2024)) -> 322.82061 | J16: =J15/((1+$W$4)^(J2-2024)) -> 333.83298 | K16: =K15/((1+$W$4)^(K2-2024)) -> 344.91157 | L16: =L15/((1+$W$4)^(L2-2024)) -> 356.06754 | M16: =M15/((1+$W$4)^(M2-2024)) -> 367.31176 | O16: =O15/((1+$W$4)^(O2-2024)) -> 259.54903 | P16: =P15/((1+$W$4)^(P2-2024)) -> 263.51288 | Q16: =Q15/((1+$W$4)^(Q2-2024)) -> 267.36145 | R16: =R15/((1+$W$4)^(R2-2024)) -> 271.10093 | S16: =S15/((1+$W$4)^(S2-2024)) -> 274.73719
A18: Present Value of Terminal Value | B18: =((G16*(1+$W$12))/($W$4-$W$12))/((1+$W$4)^5) -> 3925.5878 | H18: =((M16*(1+$W$12))/($W$4-$W$12))/((1+$W$4)^5) -> 7443.119 | N18: =((S16*(1+$W$12))/($W$4-$W$12))/((1+$W$4)^5) -> 5567.2097
A19: Segment Enterprise Value | B19: =B18+SUM(C16:G16) -> 4886.8167 | H19: =H18+SUM(I16:M16) -> 9168.0635 | N19: =N18+SUM(O16:S16) -> 6903.4711
B22: =B19 -> 4886.8167 | C22: =D22-0.005 -> 0.047975388 | D22: =E22-0.005 -> 0.052975388 | E22: 0.057975388 | F22: =E22+0.005 -> 0.062975388 | G22: =F22+0.005 -> 0.067975388 | H22: =H19 -> 9168.0635 | I22: =J22-0.005 -> 0.047975388 | J22: =K22-0.005 -> 0.052975388 | K22: 0.057975388 | L22: =K22+0.005 -> 0.062975388 | M22: =L22+0.005 -> 0.067975388 | N22: =N19 -> 6903.4711 | O22: =P22-0.005 -> 0.047975388 | P22: =Q22-0.005 -> 0.052975388 | Q22: 0.057975388 | R22: =Q22+0.005 -> 0.062975388 | S22: =R22+0.005 -> 0.067975388
B23: =B24-0.005 -> 0.01 | C23: 5263.5337 | D23: 4576.5342 | E23: 4038.1023 | F23: 3605.8498 | G23: 3252.0302 | H23: =H24-0.005 -> 0.01 | I23: 9880.4455 | J23: 8578.813 | K23: 7558.8567 | L23: 6740.2065 | M23: 6070.2542 | N23: =N24-0.005 -> 0.01 | O23: 7437.2031 | P23: 6463.174 | Q23: 5699.8371 | R23: 5087.0778 | S23: 4585.5469
B24: =B25-0.005 -> 0.015 | C24: 5936.0155 | D24: 5070.8976 | E24: 4413.0874 | F24: 3897.4117 | G24: 3483.3237 | H24: =H25-0.005 -> 0.015 | I24: 11155.506 | J24: 9516.1519 | K24: 8269.848 | L24: 7293.0232 | M24: 6508.7987 | N24: =N25-0.005 -> 0.015 | O24: 8390.9066 | P24: 7164.2729 | Q24: 6231.6353 | R24: 5500.5666 | S24: 4913.5638
B25: 0.02 | C25: 6848.8806 | D25: 5715.18 | E25: 4886.8167 | F25: 4256.8177 | G25: 3762.8281 | H25: 0.02 | I25: 12886.346 | J25: 10737.745 | K25: 9168.0635 | L25: 7974.4755 | M25: 7038.7535 | N25: 0.02 | O25: 9685.5182 | P25: 8077.9845 | Q25: 6903.4711 | R25: 6010.2707 | S25: 5309.9527
B26: =B25+0.005 -> 0.025 | C26: 8159.0687 | D26: 6589.7657 | E26: 5504.2076 | F26: 4710.8654 | G26: 4107.3706 | H26: =H25+0.005 -> 0.025 | I26: 15370.531 | J26: 12396.005 | K26: 10338.669 | L26: 8835.3736 | M26: 7692.0242 | N26: =N25+0.005 -> 0.025 | O26: 11543.607 | P26: 9318.3088 | Q26: 7779.0456 | R26: 6654.1943 | S26: 5798.5778
B27: =B26+0.005 -> 0.03 | C27: 10198.136 | D27: 7845.0134 | E27: 6342.2891 | F27: 5302.606 | G27: 4542.6411 | H27: =H26+0.005 -> 0.03 | I27: 19236.708 | J27: 14776.02 | K27: 11927.715 | L27: 9957.3447 | M27: 8517.3196 | N27: =N26+0.005 -> 0.03 | O27: 14435.382 | P27: 11098.482 | Q27: 8967.6002 | R27: 7493.392 | S27: 6415.8717
A28: Case: | B28: Bull | H28: Bull | N28: Bull
A29: Enterprise Value: | B29: =IF(B28="Bull",D26,IF(B28="Bear",F24,IF(B28="Central",E25,"Error"))) -> 6589.7657 | H29: =IF(H28="Bull",J26,IF(H28="Bear",L24,IF(H28="Central",K25,"Error"))) -> 12396.005 | N29: =IF(N28="Bull",P26,IF(N28="Bear",R24,IF(N28="Central",Q25,"Error"))) -> 9318.3088
A31: Net Debt | B31: =DCF!B25 -> 2986
A32: Implied Equity Value | B32: =B29+H29+N29-B31 -> 25318.08
A33: Equity Value per Ordinary Share | B33: =B32/DCF!B36 -> 28.901917
A34: Equity Value per ADR Share | B34: =B33*2 -> 57.803835
A35: Share Price | B35: =DCF!I9 -> 36.82
A36: Upside | B36: =B34-B35 -> 20.983835 | C36: =B36/B35 -> 0.56990317
A38: Segmental TAM | B38: 7250 | H38: 16800 | N38: 12140

Sheet rNPV
A1: Bull
A2: Asset / Segment | B2: AGILI-C Cartilage Implant (Sports Med) | J2: REGENETEN – Extra-articular Ligaments (Sports Med) | R2: CORIOGRAPH Pre-Op Planning (Orthopaedics) | Z2: LEGION TKS Medial-Stabilised Insert (Orthopaedics) | AH2: ALLEVYN COMPLETE CARE 5-Layer Foam (Advanced Wound) | AP2: CENTRIO PRP System (Advanced Wound)
A3: FY | B3: =YEAR(DATEVALUE("JAN-2025")) -> 2025 | C3: =YEAR(DATEVALUE("JAN-2026")) -> 2026 | D3: =YEAR(DATEVALUE("JAN-2027")) -> 2027 | E3: =YEAR(DATEVALUE("JAN-2028")) -> 2028 | F3: =YEAR(DATEVALUE("JAN-2029")) -> 2029 | G3: =YEAR(DATEVALUE("JAN-2030")) -> 2030 | H3: =YEAR(DATEVALUE("JAN-2031")) -> 2031 | I3: =YEAR(DATEVALUE("JAN-2032")) -> 2032 | J3: =YEAR(DATEVALUE("JAN-2025")) -> 2025 | K3: =YEAR(DATEVALUE("JAN-2026")) -> 2026 | L3: =YEAR(DATEVALUE("JAN-2027")) -> 2027 | M3: =YEAR(DATEVALUE("JAN-2028")) -> 2028 | N3: =YEAR(DATEVALUE("JAN-2029")) -> 2029 | O3: =YEAR(DATEVALUE("JAN-2030")) -> 2030 | P3: =YEAR(DATEVALUE("JAN-2031")) -> 2031 | Q3: =YEAR(DATEVALUE("JAN-2032")) -> 2032 | R3: =YEAR(DATEVALUE("JAN-2025")) -> 2025 | S3: =YEAR(DATEVALUE("JAN-2026")) -> 2026 | T3: =YEAR(DATEVALUE("JAN-2027")) -> 2027 | U3: =YEAR(DATEVALUE("JAN-2028")) -> 2028 | V3: =YEAR(DATEVALUE("JAN-2029")) -> 2029 | W3: =YEAR(DATEVALUE("JAN-2030")) -> 2030 | X3: =YEAR(DATEVALUE("JAN-2031")) -> 2031 | Y3: =YEAR(DATEVALUE("JAN-2032")) -> 2032 | Z3: =YEAR(DATEVALUE("JAN-2025")) -> 2025 | AA3: =YEAR(DATEVALUE("JAN-2026")) -> 2026 | AB3: =YEAR(DATEVALUE("JAN-2027")) -> 2027 | AC3: =YEAR(DATEVALUE("JAN-2028")) -> 2028 | AD3: =YEAR(DATEVALUE("JAN-2029")) -> 2029 | AE3: =YEAR(DATEVALUE("JAN-2030")) -> 2030 | AF3: =YEAR(DATEVALUE("JAN-2031")) -> 2031 | AG3: =YEAR(DATEVALUE("JAN-2032")) -> 2032 | AH3: =YEAR(DATEVALUE("JAN-2025")) -> 2025 | AI3: =YEAR(DATEVALUE("JAN-2026")) -> 2026 | AJ3: =YEAR(DATEVALUE("JAN-2027")) -> 2027 | AK3: =YEAR(DATEVALUE("JAN-2028")) -> 2028 | AL3: =YEAR(DATEVALUE("JAN-2029")) -> 2029 | AM3: =YEAR(DATEVALUE("JAN-2030")) -> 2030 | AN3: =YEAR(DATEVALUE("JAN-2031")) -> 2031 | AO3: =YEAR(DATEVALUE("JAN-2032")) -> 2032 | AP3: =YEAR(DATEVALUE("JAN-2025")) -> 2025 | AQ3: =YEAR(DATEVALUE("JAN-2026")) -> 2026 | AR3: =YEAR(DATEVALUE("JAN-2027")) -> 2027 | AS3: =YEAR(DATEVALUE("JAN-2028")) -> 2028 | AT3: =YEAR(DATEVALUE("JAN-2029")) -> 2029 | AU3: =YEAR(DATEVALUE("JAN-2030")) -> 2030 | AV3: =YEAR(DATEVALUE("JAN-2031")) -> 2031 | AW3: =YEAR(DATEVALUE("JAN-2032")) -> 2032 | BF3: Asset / Segment | BG3: Ag | BH3: R | BI3: Co | BJ3: L | BK3: Al | BL3: Ce
A4: Implied TAM | B4: =BG17*(1+$AZ$11)*(1-_xlfn.XLOOKUP(Scenario,AY7:AY9,BC7:BC9,,0)) -> 291.363 | C4: =B4*(1+$AZ$11)*(1-_xlfn.XLOOKUP(Scenario,AY7:AY9,BC7:BC9,,0)) -> 292.73241 | D4: =C4*(1+$AZ$11)*(1-_xlfn.XLOOKUP(Scenario,AY7:AY9,BC7:BC9,,0)) -> 294.10825 | E4: =D4*(1+$AZ$11)*(1-_xlfn.XLOOKUP(Scenario,AY7:AY9,BC7:BC9,,0)) -> 295.49056 | F4: =E4*(1+$AZ$11)*(1-_xlfn.XLOOKUP(Scenario,AY7:AY9,BC7:BC9,,0)) -> 296.87936 | G4: =F4*(1+$AZ$11)*(1-_xlfn.XLOOKUP(Scenario,AY7:AY9,BC7:BC9,,0)) -> 298.2747 | H4: =G4*(1+$AZ$11)*(1-_xlfn.XLOOKUP(Scenario,AY7:AY9,BC7:BC9,,0)) -> 299.67659 | I4: =H4*(1+$AZ$11)*(1-_xlfn.XLOOKUP(Scenario,AY7:AY9,BC7:BC9,,0)) -> 301.08507 | J4: =BH17*(1+$AZ$11)*(1-_xlfn.XLOOKUP(Scenario,AY7:AY9,BC7:BC9,,0)) -> 218.52225 | K4: =J4*(1+$AZ$11)*(1-_xlfn.XLOOKUP(Scenario,AY7:AY9,BC7:BC9,,0)) -> 219.5493 | L4: =K4*(1+$AZ$11)*(1-_xlfn.XLOOKUP(Scenario,AY7:AY9,BC7:BC9,,0)) -> 220.58119 | M4: =L4*(1+$AZ$11)*(1-_xlfn.XLOOKUP(Scenario,AY7:AY9,BC7:BC9,,0)) -> 221.61792 | N4: =M4*(1+$AZ$11)*(1-_xlfn.XLOOKUP(Scenario,AY7:AY9,BC7:BC9,,0)) -> 222.65952 | O4: =N4*(1+$AZ$11)*(1-_xlfn.XLOOKUP(Scenario,AY7:AY9,BC7:BC9,,0)) -> 223.70602 | P4: =O4*(1+$AZ$11)*(1-_xlfn.XLOOKUP(Scenario,AY7:AY9,BC7:BC9,,0)) -> 224.75744 | Q4: =P4*(1+$AZ$11)*(1-_xlfn.XLOOKUP(Scenario,AY7:AY9,BC7:BC9,,0)) -> 225.8138 | R4: =BI17*(1+$AZ$11)*(1-_xlfn.XLOOKUP(Scenario,AY7:AY9,BC7:BC9,,0)) -> 337.5792 | S4: =R4*(1+$AZ$11)*(1-_xlfn.XLOOKUP(Scenario,AY7:AY9,BC7:BC9,,0)) -> 339.16582 | T4: =S4*(1+$AZ$11)*(1-_xlfn.XLOOKUP(Scenario,AY7:AY9,BC7:BC9,,0)) -> 340.7599 | U4: =T4*(1+$AZ$11)*(1-_xlfn.XLOOKUP(Scenario,AY7:AY9,BC7:BC9,,0)) -> 342.36147 | V4: =U4*(1+$AZ$11)*(1-_xlfn.XLOOKUP(Scenario,AY7:AY9,BC7:BC9,,0)) -> 343.97057 | W4: =V4*(1+$AZ$11)*(1-_xlfn.XLOOKUP(Scenario,AY7:AY9,BC7:BC9,,0)) -> 345.58723 | X4: =W4*(1+$AZ$11)*(1-_xlfn.XLOOKUP(Scenario,AY7:AY9,BC7:BC9,,0)) -> 347.21149 | Y4: =X4*(1+$AZ$11)*(1-_xlfn.XLOOKUP(Scenario,AY7:AY9,BC7:BC9,,0)) -> 348.84339 | Z4: =BJ17*(1+$AZ$11)*(1-_xlfn.XLOOKUP(Scenario,AY7:AY9,BC7:BC9,,0)) -> 421.974 | AA4: =Z4*(1+$AZ$11)*(1-_xlfn.XLOOKUP(Scenario,AY7:AY9,BC7:BC9,,0)) -> 423.95728 | AB4: =AA4*(1+$AZ$11)*(1-_xlfn.XLOOKUP(Scenario,AY7:AY9,BC7:BC9,,0)) -> 425.94988 | AC4: =AB4*(1+$AZ$11)*(1-_xlfn.XLOOKUP(Scenario,AY7:AY9,BC7:BC9,,0)) -> 427.95184 | AD4: =AC4*(1+$AZ$11)*(1-_xlfn.XLOOKUP(Scenario,AY7:AY9,BC7:BC9,,0)) -> 429.96322 | AE4: =AD4*(1+$AZ$11)*(1-_xlfn.XLOOKUP(Scenario,AY7:AY9,BC7:BC9,,0)) -> 431.98404 | AF4: =AE4*(1+$AZ$11)*(1-_xlfn.XLOOKUP(Scenario,AY7:AY9,BC7:BC9,,0)) -> 434.01437 | AG4: =AF4*(1+$AZ$11)*(1-_xlfn.XLOOKUP(Scenario,AY7:AY9,BC7:BC9,,0)) -> 436.05423 | AH4: =BK17*(1+$AZ$11)*(1-_xlfn.XLOOKUP(Scenario,AY7:AY9,BC7:BC9,,0)) -> 182.95587 | AI4: =AH4*(1+$AZ$11)*(1-_xlfn.XLOOKUP(Scenario,AY7:AY9,BC7:BC9,,0)) -> 183.81576 | AJ4: =AI4*(1+$AZ$11)*(1-_xlfn.XLOOKUP(Scenario,AY7:AY9,BC7:BC9,,0)) -> 184.6797 | AK4: =AJ4*(1+$AZ$11)*(1-_xlfn.XLOOKUP(Scenario,AY7:AY9,BC7:BC9,,0)) -> 185.54769 | AL4: =AK4*(1+$AZ$11)*(1-_xlfn.XLOOKUP(Scenario,AY7:AY9,BC7:BC9,,0)) -> 186.41977 | AM4: =AL4*(1+$AZ$11)*(1-_xlfn.XLOOKUP(Scenario,AY7:AY9,BC7:BC9,,0)) -> 187.29594 | AN4: =AM4*(1+$AZ$11)*(1-_xlfn.XLOOKUP(Scenario,AY7:AY9,BC7:BC9,,0)) -> 188.17623 | AO4: =AN4*(1+$AZ$11)*(1-_xlfn.XLOOKUP(Scenario,AY7:AY9,BC7:BC9,,0)) -> 189.06066 | AP4: =BL17*(1+$AZ$11)*(1-_xlfn.XLOOKUP(Scenario,AY7:AY9,BC7:BC9,,0)) -> 365.91174 | AQ4: =AP4*(1+$AZ$11)*(1-_xlfn.XLOOKUP(Scenario,AY7:AY9,BC7:BC9,,0)) -> 367.63153 | AR4: =AQ4*(1+$AZ$11)*(1-_xlfn.XLOOKUP(Scenario,AY7:AY9,BC7:BC9,,0)) -> 369.35939 | AS4: =AR4*(1+$AZ$11)*(1-_xlfn.XLOOKUP(Scenario,AY7:AY9,BC7:BC9,,0)) -> 371.09538 | AT4: =AS4*(1+$AZ$11)*(1-_xlfn.XLOOKUP(Scenario,AY7:AY9,BC7:BC9,,0)) -> 372.83953 | AU4: =AT4*(1+$AZ$11)*(1-_xlfn.XLOOKUP(Scenario,AY7:AY9,BC7:BC9,,0)) -> 374.59188 | AV4: =AU4*(1+$AZ$11)*(1-_xlfn.XLOOKUP(Scenario,AY7:AY9,BC7:BC9,,0)) -> 376.35246 | AW4: =AV4*(1+$AZ$11)*(1-_xlfn.XLOOKUP(Scenario,AY7:AY9,BC7:BC9,,0)) -> 378.12131 | BF4: Targeted Launch | BG4: 2027 | BH4: 2028 | BI4: 2027 | BJ4: 2027 | BK4: 2027 | BL4: 2028
A5: Adoption Curve | BE5: Success | BF5: Bear | BG5: 0.35 | BH5: 0.25 | BI5: 0.45 | BJ5: 0.4 | BK5: 0.45 | BL5: 0.3
A6: Modelled by:y=-x^2+2x | B6: =IF(B3<$BG$4,0,-(MIN(1,MAX(0,((B3-$BG$4+1)*_xlfn.XLOOKUP(Scenario,$AY$7:$AY$9,$BA$7:$BA$9,1,0)/$BG$18)))^2)+2*MIN(1,MAX(0,((B3-$BG$4+1)*_xlfn.XLOOKUP(Scenario,$AY$7:$AY$9,$BA$7:$BA$9,1,0)/$BG$18)))) -> 0 | C6: =IF(C3<$BG$4,0,-(MIN(1,MAX(0,((C3-$BG$4+1)*_xlfn.XLOOKUP(Scenario,$AY$7:$AY$9,$BA$7:$BA$9,1,0)/$BG$18)))^2)+2*MIN(1,MAX(0,((C3-$BG$4+1)*_xlfn.XLOOKUP(Scenario,$AY$7:$AY$9,$BA$7:$BA$9,1,0)/$BG$18)))) -> 0 | D6: =IF(D3<$BG$4,0,-(MIN(1,MAX(0,((D3-$BG$4+1)*_xlfn.XLOOKUP(Scenario,$AY$7:$AY$9,$BA$7:$BA$9,1,0)/$BG$18)))^2)+2*MIN(1,MAX(0,((D3-$BG$4+1)*_xlfn.XLOOKUP(Scenario,$AY$7:$AY$9,$BA$7:$BA$9,1,0)/$BG$18)))) -> 0.3916 | E6: =IF(E3<$BG$4,0,-(MIN(1,MAX(0,((E3-$BG$4+1)*_xlfn.XLOOKUP(Scenario,$AY$7:$AY$9,$BA$7:$BA$9,1,0)/$BG$18)))^2)+2*MIN(1,MAX(0,((E3-$BG$4+1)*_xlfn.XLOOKUP(Scenario,$AY$7:$AY$9,$BA$7:$BA$9,1,0)/$BG$18)))) -> 0.6864 | F6: =IF(F3<$BG$4,0,-(MIN(1,MAX(0,((F3-$BG$4+1)*_xlfn.XLOOKUP(Scenario,$AY$7:$AY$9,$BA$7:$BA$9,1,0)/$BG$18)))^2)+2*MIN(1,MAX(0,((F3-$BG$4+1)*_xlfn.XLOOKUP(Scenario,$AY$7:$AY$9,$BA$7:$BA$9,1,0)/$BG$18)))) -> 0.8844 | G6: =IF(G3<$BG$4,0,-(MIN(1,MAX(0,((G3-$BG$4+1)*_xlfn.XLOOKUP(Scenario,$AY$7:$AY$9,$BA$7:$BA$9,1,0)/$BG$18)))^2)+2*MIN(1,MAX(0,((G3-$BG$4+1)*_xlfn.XLOOKUP(Scenario,$AY$7:$AY$9,$BA$7:$BA$9,1,0)/$BG$18)))) -> 0.9856 | H6: =IF(H3<$BG$4,0,-(MIN(1,MAX(0,((H3-$BG$4+1)*_xlfn.XLOOKUP(Scenario,$AY$7:$AY$9,$BA$7:$BA$9,1,0)/$BG$18)))^2)+2*MIN(1,MAX(0,((H3-$BG$4+1)*_xlfn.XLOOKUP(Scenario,$AY$7:$AY$9,$BA$7:$BA$9,1,0)/$BG$18)))) -> 1 | I6: =IF(I3<$BG$4,0,-(MIN(1,MAX(0,((I3-$BG$4+1)*_xlfn.XLOOKUP(Scenario,$AY$7:$AY$9,$BA$7:$BA$9,1,0)/$BG$18)))^2)+2*MIN(1,MAX(0,((I3-$BG$4+1)*_xlfn.XLOOKUP(Scenario,$AY$7:$AY$9,$BA$7:$BA$9,1,0)/$BG$18)))) -> 1 | J6: =IF(J3<$BH$4,0,-(MIN(1,MAX(0,((J3-$BH$4+1)*_xlfn.XLOOKUP(Scenario,$AY$7:$AY$9,$BA$7:$BA$9,1,0)/$BH$18)))^2)+2*MIN(1,MAX(0,((J3-$BH$4+1)*_xlfn.XLOOKUP(Scenario,$AY$7:$AY$9,$BA$7:$BA$9,1,0)/$BH$18)))) -> 0 | K6: =IF(K3<$BH$4,0,-(MIN(1,MAX(0,((K3-$BH$4+1)*_xlfn.XLOOKUP(Scenario,$AY$7:$AY$9,$BA$7:$BA$9,1,0)/$BH$18)))^2)+2*MIN(1,MAX(0,((K3-$BH$4+1)*_xlfn.XLOOKUP(Scenario,$AY$7:$AY$9,$BA$7:$BA$9,1,0)/$BH$18)))) -> 0 | L6: =IF(L3<$BH$4,0,-(MIN(1,MAX(0,((L3-$BH$4+1)*_xlfn.XLOOKUP(Scenario,$AY$7:$AY$9,$BA$7:$BA$9,1,0)/$BH$18)))^2)+2*MIN(1,MAX(0,((L3-$BH$4+1)*_xlfn.XLOOKUP(Scenario,$AY$7:$AY$9,$BA$7:$BA$9,1,0)/$BH$18)))) -> 0 | M6: =IF(M3<$BH$4,0,-(MIN(1,MAX(0,((M3-$BH$4+1)*_xlfn.XLOOKUP(Scenario,$AY$7:$AY$9,$BA$7:$BA$9,1,0)/$BH$18)))^2)+2*MIN(1,MAX(0,((M3-$BH$4+1)*_xlfn.XLOOKUP(Scenario,$AY$7:$AY$9,$BA$7:$BA$9,1,0)/$BH$18)))) -> 0.474375 | N6: =IF(N3<$BH$4,0,-(MIN(1,MAX(0,((N3-$BH$4+1)*_xlfn.XLOOKUP(Scenario,$AY$7:$AY$9,$BA$7:$BA$9,1,0)/$BH$18)))^2)+2*MIN(1,MAX(0,((N3-$BH$4+1)*_xlfn.XLOOKUP(Scenario,$AY$7:$AY$9,$BA$7:$BA$9,1,0)/$BH$18)))) -> 0.7975 | O6: =IF(O3<$BH$4,0,-(MIN(1,MAX(0,((O3-$BH$4+1)*_xlfn.XLOOKUP(Scenario,$AY$7:$AY$9,$BA$7:$BA$9,1,0)/$BH$18)))^2)+2*MIN(1,MAX(0,((O3-$BH$4+1)*_xlfn.XLOOKUP(Scenario,$AY$7:$AY$9,$BA$7:$BA$9,1,0)/$BH$18)))) -> 0.969375 | P6: =IF(P3<$BH$4,0,-(MIN(1,MAX(0,((P3-$BH$4+1)*_xlfn.XLOOKUP(Scenario,$AY$7:$AY$9,$BA$7:$BA$9,1,0)/$BH$18)))^2)+2*MIN(1,MAX(0,((P3-$BH$4+1)*_xlfn.XLOOKUP(Scenario,$AY$7:$AY$9,$BA$7:$BA$9,1,0)/$BH$18)))) -> 1 | Q6: =IF(Q3<$BH$4,0,-(MIN(1,MAX(0,((Q3-$BH$4+1)*_xlfn.XLOOKUP(Scenario,$AY$7:$AY$9,$BA$7:$BA$9,1,0)/$BH$18)))^2)+2*MIN(1,MAX(0,((Q3-$BH$4+1)*_xlfn.XLOOKUP(Scenario,$AY$7:$AY$9,$BA$7:$BA$9,1,0)/$BH$18)))) -> 1 | R6: =IF(R3<$BI$4,0,-(MIN(1,MAX(0,((R3-$BI$4+1)*_xlfn.XLOOKUP(Scenario,$AY$7:$AY$9,$BA$7:$BA$9,1,0)/$BI$18)))^2)+2*MIN(1,MAX(0,((R3-$BI$4+1)*_xlfn.XLOOKUP(Scenario,$AY$7:$AY$9,$BA$7:$BA$9,1,0)/$BI$18)))) -> 0 | S6: =IF(S3<$BI$4,0,-(MIN(1,MAX(0,((S3-$BI$4+1)*_xlfn.XLOOKUP(Scenario,$AY$7:$AY$9,$BA$7:$BA$9,1,0)/$BI$18)))^2)+2*MIN(1,MAX(0,((S3-$BI$4+1)*_xlfn.XLOOKUP(Scenario,$AY$7:$AY$9,$BA$7:$BA$9,1,0)/$BI$18)))) -> 0 | T6: =IF(T3<$BI$4,0,-(MIN(1,MAX(0,((T3-$BI$4+1)*_xlfn.XLOOKUP(Scenario,$AY$7:$AY$9,$BA$7:$BA$9,1,0)/$BI$18)))^2)+2*MIN(1,MAX(0,((T3-$BI$4+1)*_xlfn.XLOOKUP(Scenario,$AY$7:$AY$9,$BA$7:$BA$9,1,0)/$BI$18)))) -> 0.59888889 | U6: =IF(U3<$BI$4,0,-(MIN(1,MAX(0,((U3-$BI$4+1)*_xlfn.XLOOKUP(Scenario,$AY$7:$AY$9,$BA$7:$BA$9,1,0)/$BI$18)))^2)+2*MIN(1,MAX(0,((U3-$BI$4+1)*_xlfn.XLOOKUP(Scenario,$AY$7:$AY$9,$BA$7:$BA$9,1,0)/$BI$18)))) -> 0.92888889 | V6: =IF(V3<$BI$4,0,-(MIN(1,MAX(0,((V3-$BI$4+1)*_xlfn.XLOOKUP(Scenario,$AY$7:$AY$9,$BA$7:$BA$9,1,0)/$BI$18)))^2)+2*MIN(1,MAX(0,((V3-$BI$4+1)*_xlfn.XLOOKUP(Scenario,$AY$7:$AY$9,$BA$7:$BA$9,1,0)/$BI$18)))) -> 1 | W6: =IF(W3<$BI$4,0,-(MIN(1,MAX(0,((W3-$BI$4+1)*_xlfn.XLOOKUP(Scenario,$AY$7:$AY$9,$BA$7:$BA$9,1,0)/$BI$18)))^2)+2*MIN(1,MAX(0,((W3-$BI$4+1)*_xlfn.XLOOKUP(Scenario,$AY$7:$AY$9,$BA$7:$BA$9,1,0)/$BI$18)))) -> 1 | X6: =IF(X3<$BI$4,0,-(MIN(1,MAX(0,((X3-$BI$4+1)*_xlfn.XLOOKUP(Scenario,$AY$7:$AY$9,$BA$7:$BA$9,1,0)/$BI$18)))^2)+2*MIN(1,MAX(0,((X3-$BI$4+1)*_xlfn.XLOOKUP(Scenario,$AY$7:$AY$9,$BA$7:$BA$9,1,0)/$BI$18)))) -> 1 | Y6: =IF(Y3<$BI$4,0,-(MIN(1,MAX(0,((Y3-$BI$4+1)*_xlfn.XLOOKUP(Scenario,$AY$7:$AY$9,$BA$7:$BA$9,1,0)/$BI$18)))^2)+2*MIN(1,MAX(0,((Y3-$BI$4+1)*_xlfn.XLOOKUP(Scenario,$AY$7:$AY$9,$BA$7:$BA$9,1,0)/$BI$18)))) -> 1 | Z6: =IF(Z3<$BJ$4,0,-(MIN(1,MAX(0,((Z3-$BJ$4+1)*_xlfn.XLOOKUP(Scenario,$AY$7:$AY$9,$BA$7:$BA$9,1,0)/$BJ$18)))^2)+2*MIN(1,MAX(0,((Z3-$BJ$4+1)*_xlfn.XLOOKUP(Scenario,$AY$7:$AY$9,$BA$7:$BA$9,1,0)/$BJ$18)))) -> 0 | AA6: =IF(AA3<$BJ$4,0,-(MIN(1,MAX(0,((AA3-$BJ$4+1)*_xlfn.XLOOKUP(Scenario,$AY$7:$AY$9,$BA$7:$BA$9,1,0)/$BJ$18)))^2)+2*MIN(1,MAX(0,((AA3-$BJ$4+1)*_xlfn.XLOOKUP(Scenario,$AY$7:$AY$9,$BA$7:$BA$9,1,0)/$BJ$18)))) -> 0 | AB6: =IF(AB3<$BJ$4,0,-(MIN(1,MAX(0,((AB3-$BJ$4+1)*_xlfn.XLOOKUP(Scenario,$AY$7:$AY$9,$BA$7:$BA$9,1,0)/$BJ$18)))^2)+2*MIN(1,MAX(0,((AB3-$BJ$4+1)*_xlfn.XLOOKUP(Scenario,$AY$7:$AY$9,$BA$7:$BA$9,1,0)/$BJ$18)))) -> 0.59888889 | AC6: =IF(AC3<$BJ$4,0,-(MIN(1,MAX(0,((AC3-$BJ$4+1)*_xlfn.XLOOKUP(Scenario,$AY$7:$AY$9,$BA$7:$BA$9,1,0)/$BJ$18)))^2)+2*MIN(1,MAX(0,((AC3-$BJ$4+1)*_xlfn.XLOOKUP(Scenario,$AY$7:$AY$9,$BA$7:$BA$9,1,0)/$BJ$18)))) -> 0.92888889 | AD6: =IF(AD3<$BJ$4,0,-(MIN(1,MAX(0,((AD3-$BJ$4+1)*_xlfn.XLOOKUP(Scenario,$AY$7:$AY$9,$BA$7:$BA$9,1,0)/$BJ$18)))^2)+2*MIN(1,MAX(0,((AD3-$BJ$4+1)*_xlfn.XLOOKUP(Scenario,$AY$7:$AY$9,$BA$7:$BA$9,1,0)/$BJ$18)))) -> 1 | AE6: =IF(AE3<$BJ$4,0,-(MIN(1,MAX(0,((AE3-$BJ$4+1)*_xlfn.XLOOKUP(Scenario,$AY$7:$AY$9,$BA$7:$BA$9,1,0)/$BJ$18)))^2)+2*MIN(1,MAX(0,((AE3-$BJ$4+1)*_xlfn.XLOOKUP(Scenario,$AY$7:$AY$9,$BA$7:$BA$9,1,0)/$BJ$18)))) -> 1 | AF6: =IF(AF3<$BJ$4,0,-(MIN(1,MAX(0,((AF3-$BJ$4+1)*_xlfn.XLOOKUP(Scenario,$AY$7:$AY$9,$BA$7:$BA$9,1,0)/$BJ$18)))^2)+2*MIN(1,MAX(0,((AF3-$BJ$4+1)*_xlfn.XLOOKUP(Scenario,$AY$7:$AY$9,$BA$7:$BA$9,1,0)/$BJ$18)))) -> 1 | AG6: =IF(AG3<$BJ$4,0,-(MIN(1,MAX(0,((AG3-$BJ$4+1)*_xlfn.XLOOKUP(Scenario,$AY$7:$AY$9,$BA$7:$BA$9,1,0)/$BJ$18)))^2)+2*MIN(1,MAX(0,((AG3-$BJ$4+1)*_xlfn.XLOOKUP(Scenario,$AY$7:$AY$9,$BA$7:$BA$9,1,0)/$BJ$18)))) -> 1 | AH6: =IF(AH3<$BK$4,0,-(MIN(1,MAX(0,((AH3-$BK$4+1)*_xlfn.XLOOKUP(Scenario,$AY$7:$AY$9,$BA$7:$BA$9,1,0)/$BK$18)))^2)+2*MIN(1,MAX(0,((AH3-$BK$4+1)*_xlfn.XLOOKUP(Scenario,$AY$7:$AY$9,$BA$7:$BA$9,1,0)/$BK$18)))) -> 0 | AI6: =IF(AI3<$BK$4,0,-(MIN(1,MAX(0,((AI3-$BK$4+1)*_xlfn.XLOOKUP(Scenario,$AY$7:$AY$9,$BA$7:$BA$9,1,0)/$BK$18)))^2)+2*MIN(1,MAX(0,((AI3-$BK$4+1)*_xlfn.XLOOKUP(Scenario,$AY$7:$AY$9,$BA$7:$BA$9,1,0)/$BK$18)))) -> 0 | AJ6: =IF(AJ3<$BK$4,0,-(MIN(1,MAX(0,((AJ3-$BK$4+1)*_xlfn.XLOOKUP(Scenario,$AY$7:$AY$9,$BA$7:$BA$9,1,0)/$BK$18)))^2)+2*MIN(1,MAX(0,((AJ3-$BK$4+1)*_xlfn.XLOOKUP(Scenario,$AY$7:$AY$9,$BA$7:$BA$9,1,0)/$BK$18)))) -> 0.474375 | AK6: =IF(AK3<$BK$4,0,-(MIN(1,MAX(0,((AK3-$BK$4+1)*_xlfn.XLOOKUP(Scenario,$AY$7:$AY$9,$BA$7:$BA$9,1,0)/$BK$18)))^2)+2*MIN(1,MAX(0,((AK3-$BK$4+1)*_xlfn.XLOOKUP(Scenario,$AY$7:$AY$9,$BA$7:$BA$9,1,0)/$BK$18)))) -> 0.7975 | AL6: =IF(AL3<$BK$4,0,-(MIN(1,MAX(0,((AL3-$BK$4+1)*_xlfn.XLOOKUP(Scenario,$AY$7:$AY$9,$BA$7:$BA$9,1,0)/$BK$18)))^2)+2*MIN(1,MAX(0,((AL3-$BK$4+1)*_xlfn.XLOOKUP(Scenario,$AY$7:$AY$9,$BA$7:$BA$9,1,0)/$BK$18)))) -> 0.969375 | AM6: =IF(AM3<$BK$4,0,-(MIN(1,MAX(0,((AM3-$BK$4+1)*_xlfn.XLOOKUP(Scenario,$AY$7:$AY$9,$BA$7:$BA$9,1,0)/$BK$18)))^2)+2*MIN(1,MAX(0,((AM3-$BK$4+1)*_xlfn.XLOOKUP(Scenario,$AY$7:$AY$9,$BA$7:$BA$9,1,0)/$BK$18)))) -> 1 | AN6: =IF(AN3<$BK$4,0,-(MIN(1,MAX(0,((AN3-$BK$4+1)*_xlfn.XLOOKUP(Scenario,$AY$7:$AY$9,$BA$7:$BA$9,1,0)/$BK$18)))^2)+2*MIN(1,MAX(0,((AN3-$BK$4+1)*_xlfn.XLOOKUP(Scenario,$AY$7:$AY$9,$BA$7:$BA$9,1,0)/$BK$18)))) -> 1 | AO6: =IF(AO3<$BK$4,0,-(MIN(1,MAX(0,((AO3-$BK$4+1)*_xlfn.XLOOKUP(Scenario,$AY$7:$AY$9,$BA$7:$BA$9,1,0)/$BK$18)))^2)+2*MIN(1,MAX(0,((AO3-$BK$4+1)*_xlfn.XLOOKUP(Scenario,$AY$7:$AY$9,$BA$7:$BA$9,1,0)/$BK$18)))) -> 1 | AP6: =IF(AP3<$BL$4,0,-(MIN(1,MAX(0,((AP3-$BL$4+1)*_xlfn.XLOOKUP(Scenario,$AY$7:$AY$9,$BA$7:$BA$9,1,0)/$BL$18)))^2)+2*MIN(1,MAX(0,((AP3-$BL$4+1)*_xlfn.XLOOKUP(Scenario,$AY$7:$AY$9,$BA$7:$BA$9,1,0)/$BL$18)))) -> 0 | AQ6: =IF(AQ3<$BL$4,0,-(MIN(1,MAX(0,((AQ3-$BL$4+1)*_xlfn.XLOOKUP(Scenario,$AY$7:$AY$9,$BA$7:$BA$9,1,0)/$BL$18)))^2)+2*MIN(1,MAX(0,((AQ3-$BL$4+1)*_xlfn.XLOOKUP(Scenario,$AY$7:$AY$9,$BA$7:$BA$9,1,0)/$BL$18)))) -> 0 | AR6: =IF(AR3<$BL$4,0,-(MIN(1,MAX(0,((AR3-$BL$4+1)*_xlfn.XLOOKUP(Scenario,$AY$7:$AY$9,$BA$7:$BA$9,1,0)/$BL$18)))^2)+2*MIN(1,MAX(0,((AR3-$BL$4+1)*_xlfn.XLOOKUP(Scenario,$AY$7:$AY$9,$BA$7:$BA$9,1,0)/$BL$18)))) -> 0 | AS6: =IF(AS3<$BL$4,0,-(MIN(1,MAX(0,((AS3-$BL$4+1)*_xlfn.XLOOKUP(Scenario,$AY$7:$AY$9,$BA$7:$BA$9,1,0)/$BL$18)))^2)+2*MIN(1,MAX(0,((AS3-$BL$4+1)*_xlfn.XLOOKUP(Scenario,$AY$7:$AY$9,$BA$7:$BA$9,1,0)/$BL$18)))) -> 0.7975 | AT6: =IF(AT3<$BL$4,0,-(MIN(1,MAX(0,((AT3-$BL$4+1)*_xlfn.XLOOKUP(Scenario,$AY$7:$AY$9,$BA$7:$BA$9,1,0)/$BL$18)))^2)+2*MIN(1,MAX(0,((AT3-$BL$4+1)*_xlfn.XLOOKUP(Scenario,$AY$7:$AY$9,$BA$7:$BA$9,1,0)/$BL$18)))) -> 1 | AU6: =IF(AU3<$BL$4,0,-(MIN(1,MAX(0,((AU3-$BL$4+1)*_xlfn.XLOOKUP(Scenario,$AY$7:$AY$9,$BA$7:$BA$9,1,0)/$BL$18)))^2)+2*MIN(1,MAX(0,((AU3-$BL$4+1)*_xlfn.XLOOKUP(Scenario,$AY$7:$AY$9,$BA$7:$BA$9,1,0)/$BL$18)))) -> 1 | AV6: =IF(AV3<$BL$4,0,-(MIN(1,MAX(0,((AV3-$BL$4+1)*_xlfn.XLOOKUP(Scenario,$AY$7:$AY$9,$BA$7:$BA$9,1,0)/$BL$18)))^2)+2*MIN(1,MAX(0,((AV3-$BL$4+1)*_xlfn.XLOOKUP(Scenario,$AY$7:$AY$9,$BA$7:$BA$9,1,0)/$BL$18)))) -> 1 | AW6: =IF(AW3<$BL$4,0,-(MIN(1,MAX(0,((AW3-$BL$4+1)*_xlfn.XLOOKUP(Scenario,$AY$7:$AY$9,$BA$7:$BA$9,1,0)/$BL$18)))^2)+2*MIN(1,MAX(0,((AW3-$BL$4+1)*_xlfn.XLOOKUP(Scenario,$AY$7:$AY$9,$BA$7:$BA$9,1,0)/$BL$18)))) -> 1 | AZ6: Sales Multiplier | BA6: Adoption Speed | BB6: Retention | BC6: Price Erosion | BE6: Success | BF6: Central | BG6: 0.65 | BH6: 0.55 | BI6: 0.7 | BJ6: 0.7 | BK6: 0.6 | BL6: 0.6
A7: Novel Revenue | B7: =B4*(B6-B1)*_xlfn.XLOOKUP(A1,AY7:AY9,AZ7:AZ9,,0) -> 0 | C7: =C4*(C6-B6)*_xlfn.XLOOKUP(A1,AY7:AY9,AZ7:AZ9,,0) -> 0 | D7: =D4*(D6-C6)*_xlfn.XLOOKUP(A1,AY7:AY9,AZ7:AZ9,,0) -> 138.20735 | E7: =E4*(E6-D6)*_xlfn.XLOOKUP(A1,AY7:AY9,AZ7:AZ9,,0) -> 104.53274 | F7: =F4*(F6-E6)*_xlfn.XLOOKUP(A1,AY7:AY9,AZ7:AZ9,,0) -> 70.538537 | G7: =G4*(G6-F6)*_xlfn.XLOOKUP(A1,AY7:AY9,AZ7:AZ9,,0) -> 36.222479 | H7: =H4*(H6-G6)*_xlfn.XLOOKUP(A1,AY7:AY9,AZ7:AZ9,,0) -> 5.1784114 | I7: =I4*(I6-H6)*_xlfn.XLOOKUP(A1,AY7:AY9,AZ7:AZ9,,0) -> 0 | J7: =J4*(J6-J1)*_xlfn.XLOOKUP(A1,AY7:AY9,AZ7:AZ9,,0) -> 0 | K7: =K4*(K6-J6)*_xlfn.XLOOKUP(A1,AY7:AY9,AZ7:AZ9,,0) -> 0 | L7: =L4*(L6-K6)*_xlfn.XLOOKUP(A1,AY7:AY9,AZ7:AZ9,,0) -> 0 | M7: =M4*(M6-L6)*_xlfn.XLOOKUP(A1,AY7:AY9,AZ7:AZ9,,0) -> 126.156 | N7: =N4*(N6-M6)*_xlfn.XLOOKUP(A1,AY7:AY9,AZ7:AZ9,,0) -> 86.33623 | O7: =O4*(O6-N6)*_xlfn.XLOOKUP(A1,AY7:AY9,AZ7:AZ9,,0) -> 46.139367 | P7: =P4*(P6-O6)*_xlfn.XLOOKUP(A1,AY7:AY9,AZ7:AZ9,,0) -> 8.2598359 | Q7: =Q4*(Q6-P6)*_xlfn.XLOOKUP(A1,AY7:AY9,AZ7:AZ9,,0) -> 0 | R7: =R4*(R6-R1)*_xlfn.XLOOKUP(A1,AY7:AY9,AZ7:AZ9,,0) -> 0 | S7: =S4*(S6-R6)*_xlfn.XLOOKUP(A1,AY7:AY9,AZ7:AZ9,,0) -> 0 | T7: =T4*(T6-S6)*_xlfn.XLOOKUP(A1,AY7:AY9,AZ7:AZ9,,0) -> 244.89278 | U7: =U4*(U6-T6)*_xlfn.XLOOKUP(A1,AY7:AY9,AZ7:AZ9,,0) -> 135.57514 | V7: =V4*(V6-U6)*_xlfn.XLOOKUP(A1,AY7:AY9,AZ7:AZ9,,0) -> 29.352155 | W7: =W4*(W6-V6)*_xlfn.XLOOKUP(A1,AY7:AY9,AZ7:AZ9,,0) -> 0 | X7: =X4*(X6-W6)*_xlfn.XLOOKUP(A1,AY7:AY9,AZ7:AZ9,,0) -> 0 | Y7: =Y4*(Y6-X6)*_xlfn.XLOOKUP(A1,AY7:AY9,AZ7:AZ9,,0) -> 0 | Z7: =Z4*(Z6-Z1)*_xlfn.XLOOKUP(A1,AY7:AY9,AZ7:AZ9,,0) -> 0 | AA7: =AA4*(AA6-Z6)*_xlfn.XLOOKUP(A1,AY7:AY9,AZ7:AZ9,,0) -> 0 | AB7: =AB4*(AB6-AA6)*_xlfn.XLOOKUP(A1,AY7:AY9,AZ7:AZ9,,0) -> 306.11598 | AC7: =AC4*(AC6-AB6)*_xlfn.XLOOKUP(A1,AY7:AY9,AZ7:AZ9,,0) -> 169.46893 | AD7: =AD4*(AD6-AC6)*_xlfn.XLOOKUP(A1,AY7:AY9,AZ7:AZ9,,0) -> 36.690194 | AE7: =AE4*(AE6-AD6)*_xlfn.XLOOKUP(A1,AY7:AY9,AZ7:AZ9,,0) -> 0 | AF7: =AF4*(AF6-AE6)*_xlfn.XLOOKUP(A1,AY7:AY9,AZ7:AZ9,,0) -> 0 | AG7: =AG4*(AG6-AF6)*_xlfn.XLOOKUP(A1,AY7:AY9,AZ7:AZ9,,0) -> 0 | AH7: =AH4*(AH6-AH1)*_xlfn.XLOOKUP(A1,AY7:AY9,AZ7:AZ9,,0) -> 0 | AI7: =AI4*(AI6-AH6)*_xlfn.XLOOKUP(A1,AY7:AY9,AZ7:AZ9,,0) -> 0 | AJ7: =AJ4*(AJ6-AI6)*_xlfn.XLOOKUP(A1,AY7:AY9,AZ7:AZ9,,0) -> 105.12892 | AK7: =AK4*(AK6-AJ6)*_xlfn.XLOOKUP(A1,AY7:AY9,AZ7:AZ9,,0) -> 71.946117 | AL7: =AL4*(AL6-AK6)*_xlfn.XLOOKUP(A1,AY7:AY9,AZ7:AZ9,,0) -> 38.449077 | AM7: =AM4*(AM6-AL6)*_xlfn.XLOOKUP(A1,AY7:AY9,AZ7:AZ9,,0) -> 6.8831257 | AN7: =AN4*(AN6-AM6)*_xlfn.XLOOKUP(A1,AY7:AY9,AZ7:AZ9,,0) -> 0 | AO7: =AO4*(AO6-AN6)*_xlfn.XLOOKUP(A1,AY7:AY9,AZ7:AZ9,,0) -> 0 | AP7: =AP4*(AP6-AP1)*_xlfn.XLOOKUP(A1,AY7:AY9,AZ7:AZ9,,0) -> 0 | AQ7: =AQ4*(AQ6-AP6)*_xlfn.XLOOKUP(A1,AY7:AY9,AZ7:AZ9,,0) -> 0 | AR7: =AR4*(AR6-AQ6)*_xlfn.XLOOKUP(A1,AY7:AY9,AZ7:AZ9,,0) -> 0 | AS7: =AS4*(AS6-AR6)*_xlfn.XLOOKUP(A1,AY7:AY9,AZ7:AZ9,,0) -> 355.13828 | AT7: =AT4*(AT6-AS6)*_xlfn.XLOOKUP(A1,AY7:AY9,AZ7:AZ9,,0) -> 90.600006 | AU7: =AU4*(AU6-AT6)*_xlfn.XLOOKUP(A1,AY7:AY9,AZ7:AZ9,,0) -> 0 | AV7: =AV4*(AV6-AU6)*_xlfn.XLOOKUP(A1,AY7:AY9,AZ7:AZ9,,0) -> 0 | AW7: =AW4*(AW6-AV6)*_xlfn.XLOOKUP(A1,AY7:AY9,AZ7:AZ9,,0) -> 0 | AY7: Bear | AZ7: 0.8 | BA7: 0.9 | BB7: 0.75 | BC7: 0.025 | BE7: Success | BF7: Bull | BG7: 0.85 | BH7: 0.75 | BI7: 0.85 | BJ7: 0.85 | BK7: 0.75 | BL7: 0.8
A8: Returning Revenue | B8: =B1*_xlfn.XLOOKUP(A1,AY7:AY9,BB7:BB9,,0) -> 0 | C8: =(B7*_xlfn.XLOOKUP(A1,AY7:AY9,BB7:BB9,,0))+B8 -> 0 | D8: =(C7*_xlfn.XLOOKUP(A1,AY7:AY9,BB7:BB9,,0))+C8 -> 0 | E8: =(D7*_xlfn.XLOOKUP(A1,AY7:AY9,BB7:BB9,,0))+D8 -> 131.29698 | F8: =(E7*_xlfn.XLOOKUP(A1,AY7:AY9,BB7:BB9,,0))+E8 -> 230.60308 | G8: =(F7*_xlfn.XLOOKUP(A1,AY7:AY9,BB7:BB9,,0))+F8 -> 297.61469 | H8: =(G7*_xlfn.XLOOKUP(A1,AY7:AY9,BB7:BB9,,0))+G8 -> 332.02605 | I8: =(H7*_xlfn.XLOOKUP(A1,AY7:AY9,BB7:BB9,,0))+H8 -> 336.94554 | J8: =J1*_xlfn.XLOOKUP(A1,AY7:AY9,BB7:BB9,,0) -> 0 | K8: =(J7*_xlfn.XLOOKUP(A1,AY7:AY9,BB7:BB9,,0))+J8 -> 0 | L8: =(K7*_xlfn.XLOOKUP(A1,AY7:AY9,BB7:BB9,,0))+K8 -> 0 | M8: =(L7*_xlfn.XLOOKUP(A1,AY7:AY9,BB7:BB9,,0))+L8 -> 0 | N8: =(M7*_xlfn.XLOOKUP(A1,AY7:AY9,BB7:BB9,,0))+M8 -> 119.8482 | O8: =(N7*_xlfn.XLOOKUP(A1,AY7:AY9,BB7:BB9,,0))+N8 -> 201.86762 | P8: =(O7*_xlfn.XLOOKUP(A1,AY7:AY9,BB7:BB9,,0))+O8 -> 245.70002 | Q8: =(P7*_xlfn.XLOOKUP(A1,AY7:AY9,BB7:BB9,,0))+P8 -> 253.54686 | R8: =R1*_xlfn.XLOOKUP(A1,AY7:AY9,BB7:BB9,,0) -> 0 | S8: =(R7*_xlfn.XLOOKUP(A1,AY7:AY9,BB7:BB9,,0))+R8 -> 0 | T8: =(S7*_xlfn.XLOOKUP(A1,AY7:AY9,BB7:BB9,,0))+S8 -> 0 | U8: =(T7*_xlfn.XLOOKUP(A1,AY7:AY9,BB7:BB9,,0))+T8 -> 232.64814 | V8: =(U7*_xlfn.XLOOKUP(A1,AY7:AY9,BB7:BB9,,0))+U8 -> 361.44453 | W8: =(V7*_xlfn.XLOOKUP(A1,AY7:AY9,BB7:BB9,,0))+V8 -> 389.32908 | X8: =(W7*_xlfn.XLOOKUP(A1,AY7:AY9,BB7:BB9,,0))+W8 -> 389.32908 | Y8: =(X7*_xlfn.XLOOKUP(A1,AY7:AY9,BB7:BB9,,0))+X8 -> 389.32908 | Z8: =Z1*_xlfn.XLOOKUP(A1,AY7:AY9,BB7:BB9,,0) -> 0 | AA8: =(Z7*_xlfn.XLOOKUP(A1,AY7:AY9,BB7:BB9,,0))+Z8 -> 0 | AB8: =(AA7*_xlfn.XLOOKUP(A1,AY7:AY9,BB7:BB9,,0))+AA8 -> 0 | AC8: =(AB7*_xlfn.XLOOKUP(A1,AY7:AY9,BB7:BB9,,0))+AB8 -> 290.81018 | AD8: =(AC7*_xlfn.XLOOKUP(A1,AY7:AY9,BB7:BB9,,0))+AC8 -> 451.80566 | AE8: =(AD7*_xlfn.XLOOKUP(A1,AY7:AY9,BB7:BB9,,0))+AD8 -> 486.66135 | AF8: =(AE7*_xlfn.XLOOKUP(A1,AY7:AY9,BB7:BB9,,0))+AE8 -> 486.66135 | AG8: =(AF7*_xlfn.XLOOKUP(A1,AY7:AY9,BB7:BB9,,0))+AF8 -> 486.66135 | AH8: =AH1*_xlfn.XLOOKUP(A1,AY7:AY9,BB7:BB9,,0) -> 0 | AI8: =(AH7*_xlfn.XLOOKUP(A1,AY7:AY9,BB7:BB9,,0))+AH8 -> 0 | AJ8: =(AI7*_xlfn.XLOOKUP(A1,AY7:AY9,BB7:BB9,,0))+AI8 -> 0 | AK8: =(AJ7*_xlfn.XLOOKUP(A1,AY7:AY9,BB7:BB9,,0))+AJ8 -> 99.872471 | AL8: =(AK7*_xlfn.XLOOKUP(A1,AY7:AY9,BB7:BB9,,0))+AK8 -> 168.22128 | AM8: =(AL7*_xlfn.XLOOKUP(A1,AY7:AY9,BB7:BB9,,0))+AL8 -> 204.74791 | AN8: =(AM7*_xlfn.XLOOKUP(A1,AY7:AY9,BB7:BB9,,0))+AM8 -> 211.28688 | AO8: =(AN7*_xlfn.XLOOKUP(A1,AY7:AY9,BB7:BB9,,0))+AN8 -> 211.28688 | AP8: =AP1*_xlfn.XLOOKUP(A1,AY7:AY9,BB7:BB9,,0) -> 0 | AQ8: =(AP7*_xlfn.XLOOKUP(A1,AY7:AY9,BB7:BB9,,0))+AP8 -> 0 | AR8: =(AQ7*_xlfn.XLOOKUP(A1,AY7:AY9,BB7:BB9,,0))+AQ8 -> 0 | AS8: =(AR7*_xlfn.XLOOKUP(A1,AY7:AY9,BB7:BB9,,0))+AR8 -> 0 | AT8: =(AS7*_xlfn.XLOOKUP(A1,AY7:AY9,BB7:BB9,,0))+AS8 -> 337.38137 | AU8: =(AT7*_xlfn.XLOOKUP(A1,AY7:AY9,BB7:BB9,,0))+AT8 -> 423.45137 | AV8: =(AU7*_xlfn.XLOOKUP(A1,AY7:AY9,BB7:BB9,,0))+AU8 -> 423.45137 | AW8: =(AV7*_xlfn.XLOOKUP(A1,AY7:AY9,BB7:BB9,,0))+AV8 -> 423.45137 | AY8: Central | AZ8: 1 | BA8: 1 | BB8: 0.85 | BC8: 0.02 | BF8: Annual Price Erosion | BG8: 0.02 | BH8: 0.03 | BI8: 0.02 | BJ8: 0.02 | BK8: 0.01 | BL8: 0.01
A9: Total Annual Revenue | B9: =SUM(B6:B8) -> 0 | C9: =SUM(C6:C8) -> 0 | D9: =SUM(D6:D8) -> 138.59895 | E9: =SUM(E6:E8) -> 236.51612 | F9: =SUM(F6:F8) -> 302.02602 | G9: =SUM(G6:G8) -> 334.82277 | H9: =SUM(H6:H8) -> 338.20446 | I9: =SUM(I6:I8) -> 337.94554 | ... AW9: =SUM(AW6:AW8) -> 424.45137 | AY9: Bull | AZ9: 1.2 | BA9: 1.1 | BB9: 0.95 | BC9: 0.015 | BF9: Estimated EBIT Margin | BG9: 0.24 | BH9: 0.26 | BI9: 0.2 | BJ9: 0.16 | BK9: 0.24 | BL9: 0.23
A10: Research & Development | B10: =-IF($BG$4-B3=1,$BG$15*$I$9,IF(B3<$BG$4,$BG$14*$I$9,0)) -> -13.517822 | C10: =-IF($BG$4-C3=1,$BG$15*$I$9,IF(C3<$BG$4,$BG$14*$I$9,0)) -> -6.7589108 | D10: =-IF($BG$4-D3=1,$BG$15*$I$9,IF(D3<$BG$4,$BG$14*$I$9,0)) -> 0 | E10: =-IF($BG$4-E3=1,$BG$15*$I$9,IF(E3<$BG$4,$BG$14*$I$9,0)) -> 0 | F10: =-IF($BG$4-F3=1,$BG$15*$I$9,IF(F3<$BG$4,$BG$14*$I$9,0)) -> 0 | G10: =-IF($BG$4-G3=1,$BG$15*$I$9,IF(G3<$BG$4,$BG$14*$I$9,0)) -> 0 | H10: =-IF($BG$4-H3=1,$BG$15*$I$9,IF(H3<$BG$4,$BG$14*$I$9,0)) -> 0 | I10: =-IF($BG$4-I3=1,$BG$15*$I$9,IF(I3<$BG$4,$BG$14*$I$9,0)) -> 0 | J10: =-IF($BH$4-J3=1,$BH$15*$Q$9,IF(J3<$BH$4,$BH$14*$Q$9,0)) -> -7.6364058 | K10: =-IF($BH$4-K3=1,$BH$15*$Q$9,IF(K3<$BH$4,$BH$14*$Q$9,0)) -> -7.6364058 | L10: =-IF($BH$4-L3=1,$BH$15*$Q$9,IF(L3<$BH$4,$BH$14*$Q$9,0)) -> -3.8182029 | M10: =-IF($BH$4-M3=1,$BH$15*$Q$9,IF(M3<$BH$4,$BH$14*$Q$9,0)) -> 0 | N10: =-IF($BH$4-N3=1,$BH$15*$Q$9,IF(N3<$BH$4,$BH$14*$Q$9,0)) -> 0 | O10: =-IF($BH$4-O3=1,$BH$15*$Q$9,IF(O3<$BH$4,$BH$14*$Q$9,0)) -> 0 | P10: =-IF($BH$4-P3=1,$BH$15*$Q$9,IF(P3<$BH$4,$BH$14*$Q$9,0)) -> 0 | Q10: =-IF($BH$4-Q3=1,$BH$15*$Q$9,IF(Q3<$BH$4,$BH$14*$Q$9,0)) -> 0 | R10: =-IF($BI$4-R3=1,$BI$15*$Y$9,IF(R3<$BI$4,$BI$14*$Y$9,0)) -> -7.8065815 | S10: =-IF($BI$4-S3=1,$BI$15*$Y$9,IF(S3<$BI$4,$BI$14*$Y$9,0)) -> -3.9032908 | T10: =-IF($BI$4-T3=1,$BI$15*$Y$9,IF(T3<$BI$4,$BI$14*$Y$9,0)) -> 0 | U10: =-IF($BI$4-U3=1,$BI$15*$Y$9,IF(U3<$BI$4,$BI$14*$Y$9,0)) -> 0 | V10: =-IF($BI$4-V3=1,$BI$15*$Y$9,IF(V3<$BI$4,$BI$14*$Y$9,0)) -> 0 | W10: =-IF($BI$4-W3=1,$BI$15*$Y$9,IF(W3<$BI$4,$BI$14*$Y$9,0)) -> 0 | X10: =-IF($BI$4-X3=1,$BI$15*$Y$9,IF(X3<$BI$4,$BI$14*$Y$9,0)) -> 0 | Y10: =-IF($BI$4-Y3=1,$BI$15*$Y$9,IF(Y3<$BI$4,$BI$14*$Y$9,0)) -> 0 | Z10: =-IF($BJ$4-Z3=1,$BJ$15*$AG$9,IF(Z3<$BJ$4,$BJ$14*$AG$9,0)) -> -17.068147 | AA10: =-IF($BJ$4-AA3=1,$BJ$15*$AG$9,IF(AA3<$BJ$4,$BJ$14*$AG$9,0)) -> -7.3149202 | AB10: =-IF($BJ$4-AB3=1,$BJ$15*$AG$9,IF(AB3<$BJ$4,$BJ$14*$AG$9,0)) -> 0 | AC10: =-IF($BJ$4-AC3=1,$BJ$15*$AG$9,IF(AC3<$BJ$4,$BJ$14*$AG$9,0)) -> 0 | AD10: =-IF($BJ$4-AD3=1,$BJ$15*$AG$9,IF(AD3<$BJ$4,$BJ$14*$AG$9,0)) -> 0 | AE10: =-IF($BJ$4-AE3=1,$BJ$15*$AG$9,IF(AE3<$BJ$4,$BJ$14*$AG$9,0)) -> 0 | AF10: =-IF($BJ$4-AF3=1,$BJ$15*$AG$9,IF(AF3<$BJ$4,$BJ$14*$AG$9,0)) -> 0 | AG10: =-IF($BJ$4-AG3=1,$BJ$15*$AG$9,IF(AG3<$BJ$4,$BJ$14*$AG$9,0)) -> 0 | AH10: =-IF($BK$4-AH3=1,$BK$15*$AO$9,IF(AH3<$BK$4,$BK$14*$AO$9,0)) -> -3.1843031 | AI10: =-IF($BK$4-AI3=1,$BK$15*$AO$9,IF(AI3<$BK$4,$BK$14*$AO$9,0)) -> -1.0614344 | AJ10: =-IF($BK$4-AJ3=1,$BK$15*$AO$9,IF(AJ3<$BK$4,$BK$14*$AO$9,0)) -> 0 | AK10: =-IF($BK$4-AK3=1,$BK$15*$AO$9,IF(AK3<$BK$4,$BK$14*$AO$9,0)) -> 0 | AL10: =-IF($BK$4-AL3=1,$BK$15*$AO$9,IF(AL3<$BK$4,$BK$14*$AO$9,0)) -> 0 | AM10: =-IF($BK$4-AM3=1,$BK$15*$AO$9,IF(AM3<$BK$4,$BK$14*$AO$9,0)) -> 0 | AN10: =-IF($BK$4-AN3=1,$BK$15*$AO$9,IF(AN3<$BK$4,$BK$14*$AO$9,0)) -> 0 | AO10: =-IF($BK$4-AO3=1,$BK$15*$AO$9,IF(AO3<$BK$4,$BK$14*$AO$9,0)) -> 0 | AP10: =-IF($BL$4-AP3=1,$BL$15*$AW$9,IF(AP3<$BL$4,$BL$14*$AW$9,0)) -> -10.611284 | AQ10: =-IF($BL$4-AQ3=1,$BL$15*$AW$9,IF(AQ3<$BL$4,$BL$14*$AW$9,0)) -> -10.611284 | AR10: =-IF($BL$4-AR3=1,$BL$15*$AW$9,IF(AR3<$BL$4,$BL$14*$AW$9,0)) -> -4.2445137 | AS10: =-IF($BL$4-AS3=1,$BL$15*$AW$9,IF(AS3<$BL$4,$BL$14*$AW$9,0)) -> 0 | AT10: =-IF($BL$4-AT3=1,$BL$15*$AW$9,IF(AT3<$BL$4,$BL$14*$AW$9,0)) -> 0 | AU10: =-IF($BL$4-AU3=1,$BL$15*$AW$9,IF(AU3<$BL$4,$BL$14*$AW$9,0)) -> 0 | AV10: =-IF($BL$4-AV3=1,$BL$15*$AW$9,IF(AV3<$BL$4,$BL$14*$AW$9,0)) -> 0 | AW10: =-IF($BL$4-AW3=1,$BL$15*$AW$9,IF(AW3<$BL$4,$BL$14*$AW$9,0)) -> 0 | BF10: Fixed Cost Fraction | BG10: 0.2 | BH10: 0.25 | BI10: 0.3 | BJ10: 0.3 | BK10: 0.35 | BL10: 0.15
A11: Fixed Operating Costs | B11: =-IF(B3>$BG$4-1,(1-$BG$9)*$I$9*$BG$10,0) -> 0 | C11: =-IF(C3>$BG$4+1,(1-$BG$9)*$I$9*$BG$10,0) -> 0 | D11: =-IF(D3>$BG$4+1,(1-$BG$9)*$I$9*$BG$10,0) -> 0 | E11: =-IF(E3>$BG$4+1,(1-$BG$9)*$I$9*$BG$10,0) -> 0 | F11: =-IF(F3>$BG$4+1,(1-$BG$9)*$I$9*$BG$10,0) -> -51.367722 | G11: =-IF(G3>$BG$4+1,(1-$BG$9)*$I$9*$BG$10,0) -> -51.367722 | H11: =-IF(H3>$BG$4+1,(1-$BG$9)*$I$9*$BG$10,0) -> -51.367722 | I11: =-IF(I3>$BG$4+1,(1-$BG$9)*$I$9*$BG$10,0) -> -51.367722 | J11: =-IF(J3>$BH$4-1,(1-$BH$9)*$Q$9*$BH$10) -> 0 | K11: =-IF(K3>$BH$4-1,(1-$BH$9)*$Q$9*$BH$10) -> 0 | L11: =-IF(L3>$BH$4-1,(1-$BH$9)*$Q$9*$BH$10) -> 0 | M11: =-IF(M3>$BH$4-1,(1-$BH$9)*$Q$9*$BH$10) -> -47.091169 | N11: =-IF(N3>$BH$4-1,(1-$BH$9)*$Q$9*$BH$10) -> -47.091169 | O11: =-IF(O3>$BH$4-1,(1-$BH$9)*$Q$9*$BH$10) -> -47.091169 | P11: =-IF(P3>$BH$4-1,(1-$BH$9)*$Q$9*$BH$10) -> -47.091169 | Q11: =-IF(Q3>$BH$4-1,(1-$BH$9)*$Q$9*$BH$10) -> -47.091169 | R11: =-IF(R3>$BI$4-1,(1-$BI$9)*$Y$9*$BI$10,) -> 0 | S11: =-IF(S3>$BI$4-1,(1-$BI$9)*$Y$9*$BI$10,) -> 0 | T11: =-IF(T3>$BI$4-1,(1-$BI$9)*$Y$9*$BI$10,) -> -93.678979 | U11: =-IF(U3>$BI$4-1,(1-$BI$9)*$Y$9*$BI$10,) -> -93.678979 | V11: =-IF(V3>$BI$4-1,(1-$BI$9)*$Y$9*$BI$10,) -> -93.678979 | W11: =-IF(W3>$BI$4-1,(1-$BI$9)*$Y$9*$BI$10,) -> -93.678979 | X11: =-IF(X3>$BI$4-1,(1-$BI$9)*$Y$9*$BI$10,) -> -93.678979 | Y11: =-IF(Y3>$BI$4-1,(1-$BI$9)*$Y$9*$BI$10,) -> -93.678979 | Z11: =-IF(Z3>$BJ$4-1,(1-$BJ$9)*$AG$9*$BJ$10) -> 0 | AA11: =-IF(AA3>$BJ$4-1,(1-$BJ$9)*$AG$9*$BJ$10) -> 0 | AB11: =-IF(AB3>$BJ$4-1,(1-$BJ$9)*$AG$9*$BJ$10) -> -122.89066 | AC11: =-IF(AC3>$BJ$4-1,(1-$BJ$9)*$AG$9*$BJ$10) -> -122.89066 | AD11: =-IF(AD3>$BJ$4-1,(1-$BJ$9)*$AG$9*$BJ$10) -> -122.89066 | AE11: =-IF(AE3>$BJ$4-1,(1-$BJ$9)*$AG$9*$BJ$10) -> -122.89066 | AF11: =-IF(AF3>$BJ$4-1,(1-$BJ$9)*$AG$9*$BJ$10) -> -122.89066 | AG11: =-IF(AG3>$BJ$4-1,(1-$BJ$9)*$AG$9*$BJ$10) -> -122.89066 | AH11: =-IF(AH3>$BK$4-1,(1-$BK$9)*$AO$9*$BK$10) -> 0 | AI11: =-IF(AI3>$BK$4-1,(1-$BK$9)*$AO$9*$BK$10) -> 0 | AJ11: =-IF(AJ3>$BK$4-1,(1-$BK$9)*$AO$9*$BK$10) -> -56.468309 | AK11: =-IF(AK3>$BK$4-1,(1-$BK$9)*$AO$9*$BK$10) -> -56.468309 | AL11: =-IF(AL3>$BK$4-1,(1-$BK$9)*$AO$9*$BK$10) -> -56.468309 | AM11: =-IF(AM3>$BK$4-1,(1-$BK$9)*$AO$9*$BK$10) -> -56.468309 | AN11: =-IF(AN3>$BK$4-1,(1-$BK$9)*$AO$9*$BK$10) -> -56.468309 | AO11: =-IF(AO3>$BK$4-1,(1-$BK$9)*$AO$9*$BK$10) -> -56.468309 | AP11: =-IF(AP3>$BL$4-1,(1-$BL$9)*$AW$9*$BL$10) -> 0 | AQ11: =-IF(AQ3>$BL$4-1,(1-$BL$9)*$AW$9*$BL$10) -> 0 | AR11: =-IF(AR3>$BL$4-1,(1-$BL$9)*$AW$9*$BL$10) -> 0 | AS11: =-IF(AS3>$BL$4-1,(1-$BL$9)*$AW$9*$BL$10) -> -49.024134 | AT11: =-IF(AT3>$BL$4-1,(1-$BL$9)*$AW$9*$BL$10) -> -49.024134 | AU11: =-IF(AU3>$BL$4-1,(1-$BL$9)*$AW$9*$BL$10) -> -49.024134 | AV11: =-IF(AV3>$BL$4-1,(1-$BL$9)*$AW$9*$BL$10) -> -49.024134 | AW11: =-IF(AW3>$BL$4-1,(1-$BL$9)*$AW$9*$BL$10) -> -49.024134 | AY11: Perpetual Growth | AZ11: 0.02 | BF11: Variable Cost Fraction | BG11: 0.8 | BH11: 0.75 | BI11: 0.7 | BJ11: 0.7 | BK11: 0.65 | BL11: 0.85
A12: Variable Operating Costs | B12: =-B9*(1-$BG$9)*$BG$11 -> 0 | C12: =-C9*(1-$BG$9)*$BG$11 -> 0 | D12: =-D9*(1-$BG$9)*$BG$11 -> -84.26816 | E12: =-E9*(1-$BG$9)*$BG$11 -> -143.8018 | F12: =-F9*(1-$BG$9)*$BG$11 -> -183.63182 | G12: =-G9*(1-$BG$9)*$BG$11 -> -203.57225 | H12: =-H9*(1-$BG$9)*$BG$11 -> -205.62831 | I12: =-I9*(1-$BG$9)*$BG$11 -> -205.47089 | J12: =-J9*(1-$BH$9)*$BH$11 -> 0 | K12: =-K9*(1-$BH$9)*$BH$11 -> 0 | L12: =-L9*(1-$BH$9)*$BH$11 -> 0 | M12: =-M9*(1-$BH$9)*$BH$11 -> -70.279858 | N12: =-N9*(1-$BH$9)*$BH$11 -> -114.87497 | O12: =-O9*(1-$BH$9)*$BH$11 -> -138.18188 | P12: =-P9*(1-$BH$9)*$BH$11 -> -141.50272 | Q12: =-Q9*(1-$BH$9)*$BH$11 -> -141.27351 | R12: =-R9*(1-$BI$9)*$BI$11 -> 0 | S12: =-S9*(1-$BI$9)*$BI$11 -> 0 | T12: =-T9*(1-$BI$9)*$BI$11 -> -137.47534 | U12: =-U9*(1-$BI$9)*$BI$11 -> -206.72522 | V12: =-V9*(1-$BI$9)*$BI$11 -> -219.40614 | W12: =-W9*(1-$BI$9)*$BI$11 -> -218.58428 | X12: =-X9*(1-$BI$9)*$BI$11 -> -218.58428 | Y12: =-Y9*(1-$BI$9)*$BI$11 -> -218.58428 | Z12: =-Z9*(1-$BJ$9)*$BJ$11 -> 0 | AA12: =-AA9*(1-$BJ$9)*$BJ$11 -> 0 | AB12: =-AB9*(1-$BJ$9)*$BJ$11 -> -180.34834 | AC12: =-AC9*(1-$BJ$9)*$BJ$11 -> -271.1903 | AD12: =-AD9*(1-$BJ$9)*$BJ$11 -> -287.82356 | AE12: =-AE9*(1-$BJ$9)*$BJ$11 -> -286.74487 | AF12: =-AF9*(1-$BJ$9)*$BJ$11 -> -286.74487 | AG12: =-AG9*(1-$BJ$9)*$BJ$11 -> -286.74487 | AH12: =-AH9*(1-$BK$9)*$BK$11 -> 0 | AI12: =-AI9*(1-$BK$9)*$BK$11 -> 0 | AJ12: =-AJ9*(1-$BK$9)*$BK$11 -> -52.168026 | AK12: =-AK9*(1-$BK$9)*$BK$11 -> -85.272348 | AL12: =-AL9*(1-$BK$9)*$BK$11 -> -102.57403 | AM12: =-AM9*(1-$BK$9)*$BK$11 -> -105.03973 | AN12: =-AN9*(1-$BK$9)*$BK$11 -> -104.86972 | AO12: =-AO9*(1-$BK$9)*$BK$11 -> -104.86972 | AP12: =-AP9*(1-$BL$9)*$BL$11 -> 0 | AQ12: =-AQ9*(1-$BL$9)*$BL$11 -> 0 | AR12: =-AR9*(1-$BL$9)*$BL$11 -> 0 | AS12: =-AS9*(1-$BL$9)*$BL$11 -> -232.95997 | AT12: =-AT9*(1-$BL$9)*$BL$11 -> -280.76831 | AU12: =-AU9*(1-$BL$9)*$BL$11 -> -277.80342 | AV12: =-AV9*(1-$BL$9)*$BL$11 -> -277.80342 | AW12: =-AW9*(1-$BL$9)*$BL$11 -> -277.80342 | AY12: Tax Rate | AZ12: =SOTP!W2 -> 0.105675 | BF12: Maintainance CapEx | BG12: 0.02 | BH12: 0.015 | BI12: 0.015 | BJ12: 0.015 | BK12: 0.015 | BL12: 0.01
A13: EBIT | B13: =SUM(B9:B12) -> -13.517822 | C13: =SUM(C9:C12) -> -6.7589108 | D13: =SUM(D9:D12) -> 54.330788 | E13: =SUM(E9:E12) -> 92.714319 | F13: =SUM(F9:F12) -> 67.026478 | G13: =SUM(G9:G12) -> 79.882805 | H13: =SUM(H9:H12) -> 81.208426 | I13: =SUM(I9:I12) -> 81.106929 | ... AW13: =SUM(AW9:AW12) -> 97.623816 | AY13: WACC: | AZ13: =SOTP!W4 -> 0.057975388 | BF13: NWC increase per Sale | BG13: 0.08 | BH13: 0.07 | BI13: 0.06 | BJ13: 0.06 | BK13: 0.06 | BL13: 0.06
A14: Tax | B14: =MAX(0,B13*$AZ$12) -> 0 | C14: =MAX(0,C13*$AZ$12) -> 0 | D14: =MAX(0,D13*$AZ$12) -> 5.741406 | E14: =MAX(0,E13*$AZ$12) -> 9.7975857 | F14: =MAX(0,F13*$AZ$12) -> 7.083023 | G14: =MAX(0,G13*$AZ$12) -> 8.4416154 | H14: =MAX(0,H13*$AZ$12) -> 8.5817004 | I14: =MAX(0,I13*$AZ$12) -> 8.5709748 | ... AW14: =MAX(0,AW13*$AZ$12) -> 10.316397 | BF14: Clinical Validation Costs | BG14: 0.04 | BH14: 0.03 | BI14: 0.02 | BJ14: 0.035 | BK14: 0.015 | BL14: 0.025
A15: Net Operating Profit After Tax | B15: =SUM(B13:B14) -> -13.517822 | C15: =SUM(C13:C14) -> -6.7589108 | D15: =SUM(D13:D14) -> 60.072194 | E15: =SUM(E13:E14) -> 102.5119 | F15: =SUM(F13:F14) -> 74.109501 | G15: =SUM(G13:G14) -> 88.32442 | H15: =SUM(H13:H14) -> 89.790127 | I15: =SUM(I13:I14) -> 89.677904 | ... AW15: =SUM(AW13:AW14) -> 107.94021 | BF15: Regulatory Costs | BG15: 0.02 | BH15: 0.015 | BI15: 0.01 | BJ15: 0.015 | BK15: 0.005 | BL15: 0.01
A16: Annual Change in NWC | B16: 0 | C16: =-(C9-B9)*$BG$13 -> 0 | D16: =-(D9-C9)*$BG$13 -> -11.087916 | E16: =-(E9-D9)*$BG$13 -> -7.8333738 | F16: =-(F9-E9)*$BG$13 -> -5.240792 | G16: =-(G9-F9)*$BG$13 -> -2.6237402 | H16: =-(H9-G9)*$BG$13 -> -0.270535 | I16: =-(I9-H9)*$BG$13 -> 0.020713646 | J16: 0 | K16: =-(K9-J9)*$BH$13 -> 0 | L16: =-(L9-K9)*$BH$13 -> 0 | M16: =-(M9-L9)*$BH$13 -> -8.8641262 | N16: =-(N9-M9)*$BH$13 -> -5.6246088 | O16: =-(O9-N9)*$BH$13 -> -2.9396101 | P16: =-(P9-O9)*$BH$13 -> -0.41884448 | Q16: =-(Q9-P9)*$BH$13 -> 0.028909426 | R16: 0 | S16: =-(S9-R9)*$BI$13 -> 0 | T16: =-(T9-S9)*$BI$13 -> -14.7295 | U16: =-(U9-T9)*$BI$13 -> -7.4196303 | V16: =-(V9-U9)*$BI$13 -> -1.3586706 | W16: =-(W9-V9)*$BI$13 -> 0.088056466 | X16: =-(X9-W9)*$BI$13 -> 0 | Y16: =-(Y9-X9)*$BI$13 -> 0 | Z16: 0 | AA16: =-(AA9-Z9)*$BJ$13 -> 0 | AB16: =-(AB9-AA9)*$BJ$13 -> -18.402892 | AC16: =-(AC9-AB9)*$BJ$13 -> -9.2695878 | AD16: =-(AD9-AC9)*$BJ$13 -> -1.6972715 | AE16: =-(AE9-AD9)*$BJ$13 -> 0.11007058 | AF16: =-(AF9-AE9)*$BJ$13 -> 0 | AG16: =-(AG9-AF9)*$BJ$13 -> 0 | AH16: 0 | AI16: =-(AI9-AH9)*$BK$13 -> 0 | AJ16: =-(AJ9-AI9)*$BK$13 -> -6.3361975 | AK16: =-(AK9-AJ9)*$BK$13 -> -4.0207678 | AL16: =-(AL9-AK9)*$BK$13 -> -2.1014187 | AM16: =-(AM9-AL9)*$BK$13 -> -0.29947781 | AN16: =-(AN9-AM9)*$BK$13 -> 0.020649377 | AO16: =-(AO9-AN9)*$BK$13 -> 0 | AP16: 0 | AQ16: =-(AQ9-AP9)*$BL$13 -> 0 | AR16: =-(AR9-AQ9)*$BL$13 -> 0 | AS16: =-(AS9-AR9)*$BL$13 -> -21.356147 | AT16: =-(AT9-AS9)*$BL$13 -> -4.3827355 | AU16: =-(AU9-AT9)*$BL$13 -> 0.27180002 | AV16: =-(AV9-AU9)*$BL$13 -> 0 | AW16: =-(AW9-AV9)*$BL$13 -> 0 | BF16: Segment Share | BG16: 0.04 | BH16: 0.03 | BI16: 0.02 | BJ16: 0.025 | BK16: 0.015 | BL16: 0.03
A17: Capital Expenditures | B17: =-B9*$BG$12 -> 0 | C17: =-C9*$BG$12 -> 0 | D17: =-D9*$BG$12 -> -2.771979 | E17: =-E9*$BG$12 -> -4.7303224 | F17: =-F9*$BG$12 -> -6.0405204 | G17: =-G9*$BG$12 -> -6.6964554 | H17: =-H9*$BG$12 -> -6.7640892 | I17: =-I9*$BG$12 -> -6.7589108 | J17: =-J9*$BH$12 -> 0 | K17: =-K9*$BH$12 -> 0 | L17: =-L9*$BH$12 -> 0 | M17: =-M9*$BH$12 -> -1.8994556 | N17: =-N9*$BH$12 -> -3.1047289 | O17: =-O9*$BH$12 -> -3.7346454 | P17: =-P9*$BH$12 -> -3.8243978 | Q17: =-Q9*$BH$12 -> -3.8182029 | R17: =-R9*$BI$12 -> 0 | S17: =-S9*$BI$12 -> 0 | T17: =-T9*$BI$12 -> -3.6823751 | U17: =-U9*$BI$12 -> -5.5372826 | V17: =-V9*$BI$12 -> -5.8769503 | W17: =-W9*$BI$12 -> -5.8549362 | X17: =-X9*$BI$12 -> -5.8549362 | Y17: =-Y9*$BI$12 -> -5.8549362 | Z17: =-Z9*$BJ$12 -> 0 | AA17: =-AA9*$BJ$12 -> 0 | AB17: =-AB9*$BJ$12 -> -4.600723 | AC17: =-AC9*$BJ$12 -> -6.91812 | AD17: =-AD9*$BJ$12 -> -7.3424378 | AE17: =-AE9*$BJ$12 -> -7.3149202 | AF17: =-AF9*$BJ$12 -> -7.3149202 | AG17: =-AG9*$BJ$12 -> -7.3149202 | AH17: =-AH9*$BK$12 -> 0 | AI17: =-AI9*$BK$12 -> 0 | AJ17: =-AJ9*$BK$12 -> -1.5840494 | AK17: =-AK9*$BK$12 -> -2.5892413 | AL17: =-AL9*$BK$12 -> -3.114596 | AM17: =-AM9*$BK$12 -> -3.1894655 | AN17: =-AN9*$BK$12 -> -3.1843031 | AO17: =-AO9*$BK$12 -> -3.1843031 | AP17: =-AP9*$BL$12 -> 0 | AQ17: =-AQ9*$BL$12 -> 0 | AR17: =-AR9*$BL$12 -> 0 | AS17: =-AS9*$BL$12 -> -3.5593578 | AT17: =-AT9*$BL$12 -> -4.2898137 | AU17: =-AU9*$BL$12 -> -4.2445137 | AV17: =-AV9*$BL$12 -> -4.2445137 | AW17: =-AW9*$BL$12 -> -4.2445137 | BF17: Implied TAM | BG17: =BG16*SOTP!B38 -> 290 | BH17: =BH16*SOTP!B38 -> 217.5 | BI17: =BI16*SOTP!H38 -> 336 | BJ17: =BJ16*SOTP!H38 -> 420 | BK17: =BK16*SOTP!N38 -> 182.1 | BL17: =BL16*SOTP!N38 -> 364.2
A18: Depreciation and Amortisation | B18: 0 | C18: =-B17 -> 0 | D18: =-C17 -> 0 | E18: =-D17 -> 2.771979 | F18: =-E17 -> 4.7303224 | G18: =-F17 -> 6.0405204 | H18: =-G17 -> 6.6964554 | I18: =-H17 -> 6.7640892 | J18: 0 | K18: =-J17 -> 0 | L18: =-K17 -> 0 | M18: =-L17 -> 0 | N18: =-M17 -> 1.8994556 | O18: =-N17 -> 3.1047289 | P18: =-O17 -> 3.7346454 | Q18: =-P17 -> 3.8243978 | R18: 0 | S18: =-R17 -> 0 | T18: =-S17 -> 0 | U18: =-T17 -> 3.6823751 | V18: =-U17 -> 5.5372826 | W18: =-V17 -> 5.8769503 | X18: =-W17 -> 5.8549362 | Y18: =-X17 -> 5.8549362 | Z18: 0 | AA18: =-Z17 -> 0 | AB18: =-AA17 -> 0 | AC18: =-AB17 -> 4.600723 | AD18: =-AC17 -> 6.91812 | AE18: =-AD17 -> 7.3424378 | AF18: =-AE17 -> 7.3149202 | AG18: =-AF17 -> 7.3149202 | AH18: 0 | AI18: =-AH17 -> 0 | AJ18: =-AI17 -> 0 | AK18: =-AJ17 -> 1.5840494 | AL18: =-AK17 -> 2.5892413 | AM18: =-AL17 -> 3.114596 | AN18: =-AM17 -> 3.1894655 | AO18: =-AN17 -> 3.1843031 | AP18: 0 | AQ18: =-AP17 -> 0 | AR18: =-AQ17 -> 0 | AS18: =-AR17 -> 0 | AT18: =-AS17 -> 3.5593578 | AU18: =-AT17 -> 4.2898137 | AV18: =-AU17 -> 4.2445137 | AW18: =-AV17 -> 4.2445137 | BF18: Years to Fully Adopt | BG18: 5 | BH18: 4 | BI18: 3 | BJ18: 3 | BK18: 4 | BL18: 2
A19: Free Cash Flow | B19: =SUM(B15:B18) -> -13.517822 | C19: =SUM(C15:C18) -> -6.7589108 | D19: =SUM(D15:D18) -> 46.212299 | E19: =SUM(E15:E18) -> 92.720188 | F19: =SUM(F15:F18) -> 67.558511 | G19: =SUM(G15:G18) -> 85.044745 | H19: =SUM(H15:H18) -> 89.451958 | I19: =SUM(I15:I18) -> 89.703796 | ... AW19: =SUM(AW15:AW18) -> 107.94021
A21: Bear Risked FCF | B21: =IF(B3<$BG$4,B19,B19*$BG$5) -> -13.517822 | C21: =IF(C3<$BG$4,C19,C19*$BG$5) -> -6.7589108 | D21: =IF(D3<$BG$4,D19,D19*$BG$5) -> 16.174305 | E21: =IF(E3<$BG$4,E19,E19*$BG$5) -> 32.452066 | F21: =IF(F3<$BG$4,F19,F19*$BG$5) -> 23.645479 | G21: =IF(G3<$BG$4,G19,G19*$BG$5) -> 29.765661 | H21: =IF(H3<$BG$4,H19,H19*$BG$5) -> 31.308185 | I21: =IF(I3<$BG$4,I19,I19*$BG$5) -> 31.396329 | J21: =IF(J3<$BG$4,J19,J19*$BH$5) -> -7.6364058 | K21: =IF(K3<$BG$4,K19,K19*$BH$5) -> -7.6364058 | L21: =IF(L3<$BG$4,L19,L19*$BH$5) -> -0.95455073 | M21: =IF(M3<$BG$4,M19,M19*$BH$5) -> -0.13143819 | N21: =IF(N3<$BG$4,N19,N19*$BH$5) -> 10.735738 | O21: =IF(O3<$BG$4,O19,O19*$BH$5) -> 16.716408 | P21: =IF(P3<$BG$4,P19,P19*$BH$5) -> 18.217648 | Q21: =IF(Q3<$BG$4,Q19,Q19*$BH$5) -> 18.302773 | R21: =IF(R3<$BG$4,R19,R19*$BI$5) -> -7.8065815 | S21: =IF(S3<$BG$4,S19,S19*$BI$5) -> -3.9032908 | T21: =IF(T3<$BG$4,T19,T19*$BI$5) -> -1.1517382 | U21: =IF(U3<$BG$4,U19,U19*$BI$5) -> 30.032273 | V21: =IF(V3<$BG$4,V19,V19*$BI$5) -> 38.398981 | W21: =IF(W3<$BG$4,W19,W19*$BI$5) -> 38.891471 | X21: =IF(X3<$BG$4,X19,X19*$BI$5) -> 38.841939 | Y21: =IF(Y3<$BG$4,Y19,Y19*$BI$5) -> 38.841939 | Z21: =IF(Z3<$BG$4,Z19,Z19*$BJ$5) -> -17.068147 | AA21: =IF(AA3<$BG$4,AA19,AA19*$BJ$5) -> -7.3149202 | AB21: =IF(AB3<$BG$4,AB19,AB19*$BJ$5) -> -7.6641748 | AC21: =IF(AC3<$BG$4,AC19,AC19*$BJ$5) -> 25.05348 | AD21: =IF(AD3<$BG$4,AD19,AD19*$BJ$5) -> 33.994117 | AE21: =IF(AE3<$BG$4,AE19,AE19*$BJ$5) -> 34.563513 | AF21: =IF(AF3<$BG$4,AF19,AF19*$BJ$5) -> 34.508477 | AG21: =IF(AG3<$BG$4,AG19,AG19*$BJ$5) -> 34.508477 | AH21: =IF(AH3<$BG$4,AH19,AH19*$BK$5) -> -3.1843031 | AI21: =IF(AI3<$BG$4,AI19,AI19*$BK$5) -> -1.0614344 | AJ21: =IF(AJ3<$BG$4,AJ19,AJ19*$BK$5) -> -4.9289804 | AK21: =IF(AK3<$BG$4,AK19,AK19*$BK$5) -> 13.100505 | AL21: =IF(AL3<$BG$4,AL19,AL19*$BK$5) -> 22.997769 | AM21: =IF(AM3<$BG$4,AM19,AM19*$BK$5) -> 25.267981 | AN21: =IF(AN3<$BG$4,AN19,AN19*$BK$5) -> 25.361407 | AO21: =IF(AO3<$BG$4,AO19,AO19*$BK$5) -> 25.349791 | AP21: =IF(AP3<$BG$4,AP19,AP19*$BL$5) -> -10.611284 | AQ21: =IF(AQ3<$BG$4,AQ19,AQ19*$BL$5) -> -10.611284 | AR21: =IF(AR3<$BG$4,AR19,AR19*$BL$5) -> -1.2733541 | AS21: =IF(AS3<$BG$4,AS19,AS19*$BL$5) -> 17.055305 | AT21: =IF(AT3<$BG$4,AT19,AT19*$BL$5) -> 31.367259 | AU21: =IF(AU3<$BG$4,AU19,AU19*$BL$5) -> 32.477194 | AV21: =IF(AV3<$BG$4,AV19,AV19*$BL$5) -> 32.382064 | AW21: =IF(AW3<$BG$4,AW19,AW19*$BL$5) -> 32.382064
A22: Discounted Bear Risked FCF | B22: =B21/((1+$AZ$13)^(B$3-2024)) -> -12.777066 | C22: =C21/((1+$AZ$13)^(C$3-2024)) -> -6.0384515 | D22: =D21/((1+$AZ$13)^(D$3-2024)) -> 13.658372 | E22: =E21/((1+$AZ$13)^(E$3-2024)) -> 25.902405 | F22: =F21/((1+$AZ$13)^(F$3-2024)) -> 17.838991 | G22: =G21/((1+$AZ$13)^(G$3-2024)) -> 21.225706 | H22: =H21/((1+$AZ$13)^(H$3-2024)) -> 21.102259 | I22: =I21/((1+$AZ$13)^(I$3-2024)) -> 20.002043 | ... AW22: =AW21/((1+$AZ$13)^(AW$3-2024)) -> 20.630037
A23: Discounted Terminal Value | B23: =((I21*(1+$AZ$11))/($AZ$13-$AZ$11))/((1+$AZ$13)^(2032-2024)) -> 537.2449 | J23: =((Q21*(1+$AZ$11))/($AZ$13-$AZ$11))/((1+$AZ$13)^(2032-2024)) -> 313.19175 | R23: =((Y21*(1+$AZ$11))/($AZ$13-$AZ$11))/((1+$AZ$13)^(2032-2024)) -> 664.65203 | Z23: =((AG21*(1+$AZ$11))/($AZ$13-$AZ$11))/((1+$AZ$13)^(2032-2024)) -> 590.49909 | AH23: =((AO21*(1+$AZ$11))/($AZ$13-$AZ$11))/((1+$AZ$13)^(2032-2024)) -> 433.7783 | AP23: =((AW21*(1+$AZ$11))/($AZ$13-$AZ$11))/((1+$AZ$13)^(2032-2024)) -> 554.11251
